[2024-04-09 13:52:04,971: WARNING/MainProcess] /usr/local/lib/python3.12/site-packages/celery/worker/consumer/consumer.py:507: CPendingDeprecationWarning: The broker_connection_retry configuration setting will no longer determine
whether broker connection retries are made during startup in Celery 6.0 and above.
If you wish to retain the existing behavior for retrying connections on startup,
you should set broker_connection_retry_on_startup to True.
  warnings.warn(

[2024-04-09 13:52:05,037: INFO/MainProcess] Connected to redis://redis:6379/0
[2024-04-09 13:52:05,038: WARNING/MainProcess] /usr/local/lib/python3.12/site-packages/celery/worker/consumer/consumer.py:507: CPendingDeprecationWarning: The broker_connection_retry configuration setting will no longer determine
whether broker connection retries are made during startup in Celery 6.0 and above.
If you wish to retain the existing behavior for retrying connections on startup,
you should set broker_connection_retry_on_startup to True.
  warnings.warn(

[2024-04-09 13:52:05,048: INFO/MainProcess] mingle: searching for neighbors
[2024-04-09 13:52:06,074: INFO/MainProcess] mingle: all alone
[2024-04-09 13:52:06,111: INFO/MainProcess] celery@5df3e4c15229 ready.
[2024-04-09 13:53:53,807: WARNING/MainProcess] /usr/local/lib/python3.12/site-packages/celery/worker/consumer/consumer.py:507: CPendingDeprecationWarning: The broker_connection_retry configuration setting will no longer determine
whether broker connection retries are made during startup in Celery 6.0 and above.
If you wish to retain the existing behavior for retrying connections on startup,
you should set broker_connection_retry_on_startup to True.
  warnings.warn(

[2024-04-09 13:53:53,863: INFO/MainProcess] Connected to redis://redis:6379/0
[2024-04-09 13:53:53,865: WARNING/MainProcess] /usr/local/lib/python3.12/site-packages/celery/worker/consumer/consumer.py:507: CPendingDeprecationWarning: The broker_connection_retry configuration setting will no longer determine
whether broker connection retries are made during startup in Celery 6.0 and above.
If you wish to retain the existing behavior for retrying connections on startup,
you should set broker_connection_retry_on_startup to True.
  warnings.warn(

[2024-04-09 13:53:53,872: INFO/MainProcess] mingle: searching for neighbors
[2024-04-09 13:53:54,898: INFO/MainProcess] mingle: all alone
[2024-04-09 13:53:54,941: INFO/MainProcess] celery@79158a2086a5 ready.
[2024-04-09 14:18:58,327: WARNING/MainProcess] /usr/local/lib/python3.12/site-packages/celery/worker/consumer/consumer.py:507: CPendingDeprecationWarning: The broker_connection_retry configuration setting will no longer determine
whether broker connection retries are made during startup in Celery 6.0 and above.
If you wish to retain the existing behavior for retrying connections on startup,
you should set broker_connection_retry_on_startup to True.
  warnings.warn(

[2024-04-09 14:18:58,383: INFO/MainProcess] Connected to redis://redis:6379/0
[2024-04-09 14:18:58,384: WARNING/MainProcess] /usr/local/lib/python3.12/site-packages/celery/worker/consumer/consumer.py:507: CPendingDeprecationWarning: The broker_connection_retry configuration setting will no longer determine
whether broker connection retries are made during startup in Celery 6.0 and above.
If you wish to retain the existing behavior for retrying connections on startup,
you should set broker_connection_retry_on_startup to True.
  warnings.warn(

[2024-04-09 14:18:58,392: INFO/MainProcess] mingle: searching for neighbors
[2024-04-09 14:18:59,413: INFO/MainProcess] mingle: all alone
[2024-04-09 14:18:59,444: INFO/MainProcess] celery@e06a205cf572 ready.
[2024-04-09 14:20:04,027: INFO/MainProcess] Task modules.services.tasks.send_activate_email_message_task[480128e9-7a62-4f8f-a429-4c89daef6ecc] received
[2024-04-09 14:22:14,440: ERROR/ForkPoolWorker-1] Task modules.services.tasks.send_activate_email_message_task[480128e9-7a62-4f8f-a429-4c89daef6ecc] raised unexpected: OSError(101, 'Network unreachable')
Traceback (most recent call last):
  File "/usr/local/lib/python3.12/site-packages/celery/app/trace.py", line 477, in trace_task
    R = retval = fun(*args, **kwargs)
                 ^^^^^^^^^^^^^^^^^^^^
  File "/usr/local/lib/python3.12/site-packages/celery/app/trace.py", line 760, in __protected_call__
    return self.run(*args, **kwargs)
           ^^^^^^^^^^^^^^^^^^^^^^^^^
  File "/app/modules/services/tasks.py", line 13, in send_activate_email_message_task
    return send_activate_email_message(user_id)
           ^^^^^^^^^^^^^^^^^^^^^^^^^^^^^^^^^^^^
  File "/app/modules/services/email.py", line 43, in send_activate_email_message
    return user.email_user(subject, message)
           ^^^^^^^^^^^^^^^^^^^^^^^^^^^^^^^^^
  File "/usr/local/lib/python3.12/site-packages/django/contrib/auth/models.py", line 402, in email_user
    send_mail(subject, message, from_email, [self.email], **kwargs)
  File "/usr/local/lib/python3.12/site-packages/django/core/mail/__init__.py", line 87, in send_mail
    return mail.send()
           ^^^^^^^^^^^
  File "/usr/local/lib/python3.12/site-packages/django/core/mail/message.py", line 298, in send
    return self.get_connection(fail_silently).send_messages([self])
           ^^^^^^^^^^^^^^^^^^^^^^^^^^^^^^^^^^^^^^^^^^^^^^^^^^^^^^^^
  File "/usr/local/lib/python3.12/site-packages/django/core/mail/backends/smtp.py", line 127, in send_messages
    new_conn_created = self.open()
                       ^^^^^^^^^^^
  File "/usr/local/lib/python3.12/site-packages/django/core/mail/backends/smtp.py", line 85, in open
    self.connection = self.connection_class(
                      ^^^^^^^^^^^^^^^^^^^^^^
  File "/usr/local/lib/python3.12/smtplib.py", line 255, in __init__
    (code, msg) = self.connect(host, port)
                  ^^^^^^^^^^^^^^^^^^^^^^^^
  File "/usr/local/lib/python3.12/smtplib.py", line 341, in connect
    self.sock = self._get_socket(host, port, self.timeout)
                ^^^^^^^^^^^^^^^^^^^^^^^^^^^^^^^^^^^^^^^^^^
  File "/usr/local/lib/python3.12/smtplib.py", line 312, in _get_socket
    return socket.create_connection((host, port), timeout,
           ^^^^^^^^^^^^^^^^^^^^^^^^^^^^^^^^^^^^^^^^^^^^^^^
  File "/usr/local/lib/python3.12/socket.py", line 852, in create_connection
    raise exceptions[0]
  File "/usr/local/lib/python3.12/socket.py", line 837, in create_connection
    sock.connect(sa)
OSError: [Errno 101] Network unreachable
[2024-04-09 14:32:04,213: WARNING/MainProcess] /usr/local/lib/python3.12/site-packages/celery/worker/consumer/consumer.py:507: CPendingDeprecationWarning: The broker_connection_retry configuration setting will no longer determine
whether broker connection retries are made during startup in Celery 6.0 and above.
If you wish to retain the existing behavior for retrying connections on startup,
you should set broker_connection_retry_on_startup to True.
  warnings.warn(

[2024-04-09 14:32:04,298: INFO/MainProcess] Connected to redis://redis:6379/0
[2024-04-09 14:32:04,300: WARNING/MainProcess] /usr/local/lib/python3.12/site-packages/celery/worker/consumer/consumer.py:507: CPendingDeprecationWarning: The broker_connection_retry configuration setting will no longer determine
whether broker connection retries are made during startup in Celery 6.0 and above.
If you wish to retain the existing behavior for retrying connections on startup,
you should set broker_connection_retry_on_startup to True.
  warnings.warn(

[2024-04-09 14:32:04,322: INFO/MainProcess] mingle: searching for neighbors
[2024-04-09 14:32:05,353: INFO/MainProcess] mingle: all alone
[2024-04-09 14:32:05,399: INFO/MainProcess] celery@9199b09c04f5 ready.
[2024-04-09 14:33:25,983: INFO/MainProcess] Task modules.services.tasks.send_activate_email_message_task[cf37e4d0-865b-4e93-b675-9ad2fc020f72] received
[2024-04-09 14:35:37,256: ERROR/ForkPoolWorker-1] Task modules.services.tasks.send_activate_email_message_task[cf37e4d0-865b-4e93-b675-9ad2fc020f72] raised unexpected: OSError(101, 'Network unreachable')
Traceback (most recent call last):
  File "/usr/local/lib/python3.12/site-packages/celery/app/trace.py", line 477, in trace_task
    R = retval = fun(*args, **kwargs)
                 ^^^^^^^^^^^^^^^^^^^^
  File "/usr/local/lib/python3.12/site-packages/celery/app/trace.py", line 760, in __protected_call__
    return self.run(*args, **kwargs)
           ^^^^^^^^^^^^^^^^^^^^^^^^^
  File "/app/modules/services/tasks.py", line 13, in send_activate_email_message_task
    return send_activate_email_message(user_id)
           ^^^^^^^^^^^^^^^^^^^^^^^^^^^^^^^^^^^^
  File "/app/modules/services/email.py", line 43, in send_activate_email_message
    return user.email_user(subject, message)
           ^^^^^^^^^^^^^^^^^^^^^^^^^^^^^^^^^
  File "/usr/local/lib/python3.12/site-packages/django/contrib/auth/models.py", line 402, in email_user
    send_mail(subject, message, from_email, [self.email], **kwargs)
  File "/usr/local/lib/python3.12/site-packages/django/core/mail/__init__.py", line 87, in send_mail
    return mail.send()
           ^^^^^^^^^^^
  File "/usr/local/lib/python3.12/site-packages/django/core/mail/message.py", line 298, in send
    return self.get_connection(fail_silently).send_messages([self])
           ^^^^^^^^^^^^^^^^^^^^^^^^^^^^^^^^^^^^^^^^^^^^^^^^^^^^^^^^
  File "/usr/local/lib/python3.12/site-packages/django/core/mail/backends/smtp.py", line 127, in send_messages
    new_conn_created = self.open()
                       ^^^^^^^^^^^
  File "/usr/local/lib/python3.12/site-packages/django/core/mail/backends/smtp.py", line 85, in open
    self.connection = self.connection_class(
                      ^^^^^^^^^^^^^^^^^^^^^^
  File "/usr/local/lib/python3.12/smtplib.py", line 255, in __init__
    (code, msg) = self.connect(host, port)
                  ^^^^^^^^^^^^^^^^^^^^^^^^
  File "/usr/local/lib/python3.12/smtplib.py", line 341, in connect
    self.sock = self._get_socket(host, port, self.timeout)
                ^^^^^^^^^^^^^^^^^^^^^^^^^^^^^^^^^^^^^^^^^^
  File "/usr/local/lib/python3.12/smtplib.py", line 312, in _get_socket
    return socket.create_connection((host, port), timeout,
           ^^^^^^^^^^^^^^^^^^^^^^^^^^^^^^^^^^^^^^^^^^^^^^^
  File "/usr/local/lib/python3.12/socket.py", line 852, in create_connection
    raise exceptions[0]
  File "/usr/local/lib/python3.12/socket.py", line 837, in create_connection
    sock.connect(sa)
OSError: [Errno 101] Network unreachable
[2024-04-09 14:38:39,586: WARNING/MainProcess] /usr/local/lib/python3.12/site-packages/celery/worker/consumer/consumer.py:507: CPendingDeprecationWarning: The broker_connection_retry configuration setting will no longer determine
whether broker connection retries are made during startup in Celery 6.0 and above.
If you wish to retain the existing behavior for retrying connections on startup,
you should set broker_connection_retry_on_startup to True.
  warnings.warn(

[2024-04-09 14:38:39,647: INFO/MainProcess] Connected to redis://redis:6379/0
[2024-04-09 14:38:39,651: WARNING/MainProcess] /usr/local/lib/python3.12/site-packages/celery/worker/consumer/consumer.py:507: CPendingDeprecationWarning: The broker_connection_retry configuration setting will no longer determine
whether broker connection retries are made during startup in Celery 6.0 and above.
If you wish to retain the existing behavior for retrying connections on startup,
you should set broker_connection_retry_on_startup to True.
  warnings.warn(

[2024-04-09 14:38:39,655: INFO/MainProcess] mingle: searching for neighbors
[2024-04-09 14:38:40,682: INFO/MainProcess] mingle: all alone
[2024-04-09 14:38:40,717: INFO/MainProcess] celery@a31332bea20c ready.
[2024-04-09 14:41:19,275: INFO/MainProcess] Task modules.services.tasks.send_activate_email_message_task[703332ec-7b54-4197-acbc-850fa2882621] received
[2024-04-09 14:43:30,345: ERROR/ForkPoolWorker-1] Task modules.services.tasks.send_activate_email_message_task[703332ec-7b54-4197-acbc-850fa2882621] raised unexpected: OSError(101, 'Network unreachable')
Traceback (most recent call last):
  File "/usr/local/lib/python3.12/site-packages/celery/app/trace.py", line 477, in trace_task
    R = retval = fun(*args, **kwargs)
                 ^^^^^^^^^^^^^^^^^^^^
  File "/usr/local/lib/python3.12/site-packages/celery/app/trace.py", line 760, in __protected_call__
    return self.run(*args, **kwargs)
           ^^^^^^^^^^^^^^^^^^^^^^^^^
  File "/app/modules/services/tasks.py", line 13, in send_activate_email_message_task
    return send_activate_email_message(user_id)
           ^^^^^^^^^^^^^^^^^^^^^^^^^^^^^^^^^^^^
  File "/app/modules/services/email.py", line 43, in send_activate_email_message
    return user.email_user(subject, message)
           ^^^^^^^^^^^^^^^^^^^^^^^^^^^^^^^^^
  File "/usr/local/lib/python3.12/site-packages/django/contrib/auth/models.py", line 402, in email_user
    send_mail(subject, message, from_email, [self.email], **kwargs)
  File "/usr/local/lib/python3.12/site-packages/django/core/mail/__init__.py", line 87, in send_mail
    return mail.send()
           ^^^^^^^^^^^
  File "/usr/local/lib/python3.12/site-packages/django/core/mail/message.py", line 298, in send
    return self.get_connection(fail_silently).send_messages([self])
           ^^^^^^^^^^^^^^^^^^^^^^^^^^^^^^^^^^^^^^^^^^^^^^^^^^^^^^^^
  File "/usr/local/lib/python3.12/site-packages/django/core/mail/backends/smtp.py", line 127, in send_messages
    new_conn_created = self.open()
                       ^^^^^^^^^^^
  File "/usr/local/lib/python3.12/site-packages/django/core/mail/backends/smtp.py", line 85, in open
    self.connection = self.connection_class(
                      ^^^^^^^^^^^^^^^^^^^^^^
  File "/usr/local/lib/python3.12/smtplib.py", line 255, in __init__
    (code, msg) = self.connect(host, port)
                  ^^^^^^^^^^^^^^^^^^^^^^^^
  File "/usr/local/lib/python3.12/smtplib.py", line 341, in connect
    self.sock = self._get_socket(host, port, self.timeout)
                ^^^^^^^^^^^^^^^^^^^^^^^^^^^^^^^^^^^^^^^^^^
  File "/usr/local/lib/python3.12/smtplib.py", line 312, in _get_socket
    return socket.create_connection((host, port), timeout,
           ^^^^^^^^^^^^^^^^^^^^^^^^^^^^^^^^^^^^^^^^^^^^^^^
  File "/usr/local/lib/python3.12/socket.py", line 852, in create_connection
    raise exceptions[0]
  File "/usr/local/lib/python3.12/socket.py", line 837, in create_connection
    sock.connect(sa)
OSError: [Errno 101] Network unreachable
[2024-04-09 15:20:37,040: INFO/MainProcess] Task modules.services.tasks.send_activate_email_message_task[012d18dc-d0bd-4838-b617-71e2462751fd] received
[2024-04-09 15:22:47,587: ERROR/ForkPoolWorker-1] Task modules.services.tasks.send_activate_email_message_task[012d18dc-d0bd-4838-b617-71e2462751fd] raised unexpected: OSError(101, 'Network unreachable')
Traceback (most recent call last):
  File "/usr/local/lib/python3.12/site-packages/celery/app/trace.py", line 477, in trace_task
    R = retval = fun(*args, **kwargs)
                 ^^^^^^^^^^^^^^^^^^^^
  File "/usr/local/lib/python3.12/site-packages/celery/app/trace.py", line 760, in __protected_call__
    return self.run(*args, **kwargs)
           ^^^^^^^^^^^^^^^^^^^^^^^^^
  File "/app/modules/services/tasks.py", line 13, in send_activate_email_message_task
    return send_activate_email_message(user_id)
           ^^^^^^^^^^^^^^^^^^^^^^^^^^^^^^^^^^^^
  File "/app/modules/services/email.py", line 43, in send_activate_email_message
    return user.email_user(subject, message)
           ^^^^^^^^^^^^^^^^^^^^^^^^^^^^^^^^^
  File "/usr/local/lib/python3.12/site-packages/django/contrib/auth/models.py", line 402, in email_user
    send_mail(subject, message, from_email, [self.email], **kwargs)
  File "/usr/local/lib/python3.12/site-packages/django/core/mail/__init__.py", line 87, in send_mail
    return mail.send()
           ^^^^^^^^^^^
  File "/usr/local/lib/python3.12/site-packages/django/core/mail/message.py", line 298, in send
    return self.get_connection(fail_silently).send_messages([self])
           ^^^^^^^^^^^^^^^^^^^^^^^^^^^^^^^^^^^^^^^^^^^^^^^^^^^^^^^^
  File "/usr/local/lib/python3.12/site-packages/django/core/mail/backends/smtp.py", line 127, in send_messages
    new_conn_created = self.open()
                       ^^^^^^^^^^^
  File "/usr/local/lib/python3.12/site-packages/django/core/mail/backends/smtp.py", line 85, in open
    self.connection = self.connection_class(
                      ^^^^^^^^^^^^^^^^^^^^^^
  File "/usr/local/lib/python3.12/smtplib.py", line 255, in __init__
    (code, msg) = self.connect(host, port)
                  ^^^^^^^^^^^^^^^^^^^^^^^^
  File "/usr/local/lib/python3.12/smtplib.py", line 341, in connect
    self.sock = self._get_socket(host, port, self.timeout)
                ^^^^^^^^^^^^^^^^^^^^^^^^^^^^^^^^^^^^^^^^^^
  File "/usr/local/lib/python3.12/smtplib.py", line 312, in _get_socket
    return socket.create_connection((host, port), timeout,
           ^^^^^^^^^^^^^^^^^^^^^^^^^^^^^^^^^^^^^^^^^^^^^^^
  File "/usr/local/lib/python3.12/socket.py", line 852, in create_connection
    raise exceptions[0]
  File "/usr/local/lib/python3.12/socket.py", line 837, in create_connection
    sock.connect(sa)
OSError: [Errno 101] Network unreachable
[2024-04-09 16:31:00,091: INFO/MainProcess] Task modules.services.tasks.dbackup_task[24a234cc-50aa-4d7c-9891-835a2587a17d] received
[2024-04-09 16:31:00,136: WARNING/ForkPoolWorker-1] Waiting for database dump...
[2024-04-09 16:31:00,371: WARNING/ForkPoolWorker-1] Database successfully backed up
[2024-04-09 16:31:00,372: INFO/ForkPoolWorker-1] Task modules.services.tasks.dbackup_task[24a234cc-50aa-4d7c-9891-835a2587a17d] succeeded in 0.2766474259988172s: None
[2024-04-10 09:52:21,408: WARNING/MainProcess] /usr/local/lib/python3.12/site-packages/celery/worker/consumer/consumer.py:507: CPendingDeprecationWarning: The broker_connection_retry configuration setting will no longer determine
whether broker connection retries are made during startup in Celery 6.0 and above.
If you wish to retain the existing behavior for retrying connections on startup,
you should set broker_connection_retry_on_startup to True.
  warnings.warn(

[2024-04-10 09:52:21,476: INFO/MainProcess] Connected to redis://redis:6379/0
[2024-04-10 09:52:21,478: WARNING/MainProcess] /usr/local/lib/python3.12/site-packages/celery/worker/consumer/consumer.py:507: CPendingDeprecationWarning: The broker_connection_retry configuration setting will no longer determine
whether broker connection retries are made during startup in Celery 6.0 and above.
If you wish to retain the existing behavior for retrying connections on startup,
you should set broker_connection_retry_on_startup to True.
  warnings.warn(

[2024-04-10 09:52:21,488: INFO/MainProcess] mingle: searching for neighbors
[2024-04-10 09:52:22,515: INFO/MainProcess] mingle: all alone
[2024-04-10 09:52:22,565: INFO/MainProcess] celery@a31332bea20c ready.
[2024-04-10 09:53:53,524: INFO/MainProcess] Task modules.services.tasks.send_activate_email_message_task[e7dfc3f8-ccfa-428c-a5d7-56feaf1e551c] received
[2024-04-10 09:56:03,149: ERROR/ForkPoolWorker-1] Task modules.services.tasks.send_activate_email_message_task[e7dfc3f8-ccfa-428c-a5d7-56feaf1e551c] raised unexpected: OSError(101, 'Network unreachable')
Traceback (most recent call last):
  File "/usr/local/lib/python3.12/site-packages/celery/app/trace.py", line 477, in trace_task
    R = retval = fun(*args, **kwargs)
                 ^^^^^^^^^^^^^^^^^^^^
  File "/usr/local/lib/python3.12/site-packages/celery/app/trace.py", line 760, in __protected_call__
    return self.run(*args, **kwargs)
           ^^^^^^^^^^^^^^^^^^^^^^^^^
  File "/app/modules/services/tasks.py", line 13, in send_activate_email_message_task
    return send_activate_email_message(user_id)
           ^^^^^^^^^^^^^^^^^^^^^^^^^^^^^^^^^^^^
  File "/app/modules/services/email.py", line 43, in send_activate_email_message
    return user.email_user(subject, message)
           ^^^^^^^^^^^^^^^^^^^^^^^^^^^^^^^^^
  File "/usr/local/lib/python3.12/site-packages/django/contrib/auth/models.py", line 402, in email_user
    send_mail(subject, message, from_email, [self.email], **kwargs)
  File "/usr/local/lib/python3.12/site-packages/django/core/mail/__init__.py", line 87, in send_mail
    return mail.send()
           ^^^^^^^^^^^
  File "/usr/local/lib/python3.12/site-packages/django/core/mail/message.py", line 298, in send
    return self.get_connection(fail_silently).send_messages([self])
           ^^^^^^^^^^^^^^^^^^^^^^^^^^^^^^^^^^^^^^^^^^^^^^^^^^^^^^^^
  File "/usr/local/lib/python3.12/site-packages/django/core/mail/backends/smtp.py", line 127, in send_messages
    new_conn_created = self.open()
                       ^^^^^^^^^^^
  File "/usr/local/lib/python3.12/site-packages/django/core/mail/backends/smtp.py", line 85, in open
    self.connection = self.connection_class(
                      ^^^^^^^^^^^^^^^^^^^^^^
  File "/usr/local/lib/python3.12/smtplib.py", line 255, in __init__
    (code, msg) = self.connect(host, port)
                  ^^^^^^^^^^^^^^^^^^^^^^^^
  File "/usr/local/lib/python3.12/smtplib.py", line 341, in connect
    self.sock = self._get_socket(host, port, self.timeout)
                ^^^^^^^^^^^^^^^^^^^^^^^^^^^^^^^^^^^^^^^^^^
  File "/usr/local/lib/python3.12/smtplib.py", line 312, in _get_socket
    return socket.create_connection((host, port), timeout,
           ^^^^^^^^^^^^^^^^^^^^^^^^^^^^^^^^^^^^^^^^^^^^^^^
  File "/usr/local/lib/python3.12/socket.py", line 852, in create_connection
    raise exceptions[0]
  File "/usr/local/lib/python3.12/socket.py", line 837, in create_connection
    sock.connect(sa)
OSError: [Errno 101] Network unreachable
[2024-04-10 10:13:34,008: WARNING/MainProcess] /usr/local/lib/python3.12/site-packages/celery/worker/consumer/consumer.py:507: CPendingDeprecationWarning: The broker_connection_retry configuration setting will no longer determine
whether broker connection retries are made during startup in Celery 6.0 and above.
If you wish to retain the existing behavior for retrying connections on startup,
you should set broker_connection_retry_on_startup to True.
  warnings.warn(

[2024-04-10 10:13:34,091: INFO/MainProcess] Connected to redis://redis:6379/0
[2024-04-10 10:13:34,093: WARNING/MainProcess] /usr/local/lib/python3.12/site-packages/celery/worker/consumer/consumer.py:507: CPendingDeprecationWarning: The broker_connection_retry configuration setting will no longer determine
whether broker connection retries are made during startup in Celery 6.0 and above.
If you wish to retain the existing behavior for retrying connections on startup,
you should set broker_connection_retry_on_startup to True.
  warnings.warn(

[2024-04-10 10:13:34,104: INFO/MainProcess] mingle: searching for neighbors
[2024-04-10 10:13:35,139: INFO/MainProcess] mingle: all alone
[2024-04-10 10:13:35,190: INFO/MainProcess] celery@a31332bea20c ready.
[2024-04-10 10:14:21,220: INFO/MainProcess] Task modules.services.tasks.send_activate_email_message_task[5dcd1908-d6d9-4782-beda-be7f88110aa2] received
[2024-04-10 10:16:31,922: ERROR/ForkPoolWorker-1] Task modules.services.tasks.send_activate_email_message_task[5dcd1908-d6d9-4782-beda-be7f88110aa2] raised unexpected: OSError(101, 'Network unreachable')
Traceback (most recent call last):
  File "/usr/local/lib/python3.12/site-packages/celery/app/trace.py", line 477, in trace_task
    R = retval = fun(*args, **kwargs)
                 ^^^^^^^^^^^^^^^^^^^^
  File "/usr/local/lib/python3.12/site-packages/celery/app/trace.py", line 760, in __protected_call__
    return self.run(*args, **kwargs)
           ^^^^^^^^^^^^^^^^^^^^^^^^^
  File "/app/modules/services/tasks.py", line 13, in send_activate_email_message_task
    return send_activate_email_message(user_id)
           ^^^^^^^^^^^^^^^^^^^^^^^^^^^^^^^^^^^^
  File "/app/modules/services/email.py", line 43, in send_activate_email_message
    return user.email_user(subject, message)
           ^^^^^^^^^^^^^^^^^^^^^^^^^^^^^^^^^
  File "/usr/local/lib/python3.12/site-packages/django/contrib/auth/models.py", line 402, in email_user
    send_mail(subject, message, from_email, [self.email], **kwargs)
  File "/usr/local/lib/python3.12/site-packages/django/core/mail/__init__.py", line 87, in send_mail
    return mail.send()
           ^^^^^^^^^^^
  File "/usr/local/lib/python3.12/site-packages/django/core/mail/message.py", line 298, in send
    return self.get_connection(fail_silently).send_messages([self])
           ^^^^^^^^^^^^^^^^^^^^^^^^^^^^^^^^^^^^^^^^^^^^^^^^^^^^^^^^
  File "/usr/local/lib/python3.12/site-packages/django/core/mail/backends/smtp.py", line 127, in send_messages
    new_conn_created = self.open()
                       ^^^^^^^^^^^
  File "/usr/local/lib/python3.12/site-packages/django/core/mail/backends/smtp.py", line 85, in open
    self.connection = self.connection_class(
                      ^^^^^^^^^^^^^^^^^^^^^^
  File "/usr/local/lib/python3.12/smtplib.py", line 255, in __init__
    (code, msg) = self.connect(host, port)
                  ^^^^^^^^^^^^^^^^^^^^^^^^
  File "/usr/local/lib/python3.12/smtplib.py", line 341, in connect
    self.sock = self._get_socket(host, port, self.timeout)
                ^^^^^^^^^^^^^^^^^^^^^^^^^^^^^^^^^^^^^^^^^^
  File "/usr/local/lib/python3.12/smtplib.py", line 312, in _get_socket
    return socket.create_connection((host, port), timeout,
           ^^^^^^^^^^^^^^^^^^^^^^^^^^^^^^^^^^^^^^^^^^^^^^^
  File "/usr/local/lib/python3.12/socket.py", line 852, in create_connection
    raise exceptions[0]
  File "/usr/local/lib/python3.12/socket.py", line 837, in create_connection
    sock.connect(sa)
OSError: [Errno 101] Network unreachable
[2024-04-10 11:15:02,220: ERROR/MainProcess] Process 'ForkPoolWorker-1' pid:8 exited with 'signal 9 (SIGKILL)'
[2024-04-10 11:17:13,318: ERROR/MainProcess] Timed out waiting for UP message from <ForkProcess(ForkPoolWorker-2, started daemon)>
[2024-04-10 11:17:13,765: ERROR/MainProcess] Process 'ForkPoolWorker-2' pid:9 exited with 'signal 9 (SIGKILL)'
[2024-04-10 11:19:53,072: WARNING/MainProcess] /usr/local/lib/python3.12/site-packages/celery/worker/consumer/consumer.py:507: CPendingDeprecationWarning: The broker_connection_retry configuration setting will no longer determine
whether broker connection retries are made during startup in Celery 6.0 and above.
If you wish to retain the existing behavior for retrying connections on startup,
you should set broker_connection_retry_on_startup to True.
  warnings.warn(

[2024-04-10 11:19:58,119: ERROR/MainProcess] consumer: Cannot connect to redis://redis:6379/0: Error -3 connecting to redis:6379. Try again..
Trying again in 2.00 seconds... (1/100)

[2024-04-10 11:20:05,127: ERROR/MainProcess] consumer: Cannot connect to redis://redis:6379/0: Error -3 connecting to redis:6379. Try again..
Trying again in 4.00 seconds... (2/100)

[2024-04-10 11:20:14,135: ERROR/MainProcess] consumer: Cannot connect to redis://redis:6379/0: Error -3 connecting to redis:6379. Try again..
Trying again in 6.00 seconds... (3/100)

[2024-04-10 11:20:25,143: ERROR/MainProcess] consumer: Cannot connect to redis://redis:6379/0: Error -3 connecting to redis:6379. Try again..
Trying again in 8.00 seconds... (4/100)

[2024-04-10 11:20:38,150: ERROR/MainProcess] consumer: Cannot connect to redis://redis:6379/0: Error -3 connecting to redis:6379. Try again..
Trying again in 10.00 seconds... (5/100)

[2024-04-10 11:20:53,159: ERROR/MainProcess] consumer: Cannot connect to redis://redis:6379/0: Error -3 connecting to redis:6379. Try again..
Trying again in 12.00 seconds... (6/100)

[2024-04-10 11:21:10,173: ERROR/MainProcess] consumer: Cannot connect to redis://redis:6379/0: Error -3 connecting to redis:6379. Try again..
Trying again in 14.00 seconds... (7/100)

[2024-04-10 11:21:29,193: ERROR/MainProcess] consumer: Cannot connect to redis://redis:6379/0: Error -3 connecting to redis:6379. Try again..
Trying again in 16.00 seconds... (8/100)

[2024-04-10 11:21:50,202: ERROR/MainProcess] consumer: Cannot connect to redis://redis:6379/0: Error -3 connecting to redis:6379. Try again..
Trying again in 18.00 seconds... (9/100)

[2024-04-10 11:22:13,211: ERROR/MainProcess] consumer: Cannot connect to redis://redis:6379/0: Error -3 connecting to redis:6379. Try again..
Trying again in 20.00 seconds... (10/100)

[2024-04-10 11:22:38,221: ERROR/MainProcess] consumer: Cannot connect to redis://redis:6379/0: Error -3 connecting to redis:6379. Try again..
Trying again in 22.00 seconds... (11/100)

[2024-04-10 11:23:05,236: ERROR/MainProcess] consumer: Cannot connect to redis://redis:6379/0: Error -3 connecting to redis:6379. Try again..
Trying again in 24.00 seconds... (12/100)

[2024-04-10 11:23:34,246: ERROR/MainProcess] consumer: Cannot connect to redis://redis:6379/0: Error -3 connecting to redis:6379. Try again..
Trying again in 26.00 seconds... (13/100)

[2024-04-10 11:24:05,256: ERROR/MainProcess] consumer: Cannot connect to redis://redis:6379/0: Error -3 connecting to redis:6379. Try again..
Trying again in 28.00 seconds... (14/100)

[2024-04-10 11:24:38,283: ERROR/MainProcess] consumer: Cannot connect to redis://redis:6379/0: Error -3 connecting to redis:6379. Try again..
Trying again in 30.00 seconds... (15/100)

[2024-04-10 11:25:13,333: ERROR/MainProcess] consumer: Cannot connect to redis://redis:6379/0: Error -3 connecting to redis:6379. Try again..
Trying again in 32.00 seconds... (16/100)

[2024-04-10 11:25:50,364: ERROR/MainProcess] consumer: Cannot connect to redis://redis:6379/0: Error -3 connecting to redis:6379. Try again..
Trying again in 32.00 seconds... (16/100)

[2024-04-12 11:42:49,845: WARNING/MainProcess] /usr/local/lib/python3.12/site-packages/celery/worker/consumer/consumer.py:507: CPendingDeprecationWarning: The broker_connection_retry configuration setting will no longer determine
whether broker connection retries are made during startup in Celery 6.0 and above.
If you wish to retain the existing behavior for retrying connections on startup,
you should set broker_connection_retry_on_startup to True.
  warnings.warn(

[2024-04-12 11:42:49,897: INFO/MainProcess] Connected to redis://redis:6379/0
[2024-04-12 11:42:49,899: WARNING/MainProcess] /usr/local/lib/python3.12/site-packages/celery/worker/consumer/consumer.py:507: CPendingDeprecationWarning: The broker_connection_retry configuration setting will no longer determine
whether broker connection retries are made during startup in Celery 6.0 and above.
If you wish to retain the existing behavior for retrying connections on startup,
you should set broker_connection_retry_on_startup to True.
  warnings.warn(

[2024-04-12 11:42:49,905: INFO/MainProcess] mingle: searching for neighbors
[2024-04-12 11:42:50,927: INFO/MainProcess] mingle: all alone
[2024-04-12 11:42:50,973: INFO/MainProcess] celery@059f17bd8774 ready.
[2024-04-12 11:42:50,989: INFO/MainProcess] Task modules.services.tasks.dbackup_task[d0cbc335-c53d-47b5-bf29-6c764f8f6c56] received
[2024-04-12 11:42:51,050: WARNING/ForkPoolWorker-1] Waiting for database dump...
[2024-04-12 11:42:51,185: ERROR/ForkPoolWorker-1] Task modules.services.tasks.dbackup_task[d0cbc335-c53d-47b5-bf29-6c764f8f6c56] raised unexpected: CommandError('Unable to serialize database: cursor "_django_curs_139708522707720_sync_1" does not exist\n')
Traceback (most recent call last):
  File "/usr/local/lib/python3.12/site-packages/django/db/backends/utils.py", line 89, in _execute
    return self.cursor.execute(sql, params)
           ^^^^^^^^^^^^^^^^^^^^^^^^^^^^^^^^
psycopg2.errors.UndefinedTable: relation "auth_permission" does not exist
LINE 1: ...ntent_type_id", "auth_permission"."codename" FROM "auth_perm...
                                                             ^


The above exception was the direct cause of the following exception:

Traceback (most recent call last):
  File "/usr/local/lib/python3.12/site-packages/django/db/models/sql/compiler.py", line 1562, in execute_sql
    cursor.execute(sql, params)
  File "/usr/local/lib/python3.12/site-packages/django/db/backends/utils.py", line 102, in execute
    return super().execute(sql, params)
           ^^^^^^^^^^^^^^^^^^^^^^^^^^^^
  File "/usr/local/lib/python3.12/site-packages/django/db/backends/utils.py", line 67, in execute
    return self._execute_with_wrappers(
           ^^^^^^^^^^^^^^^^^^^^^^^^^^^^
  File "/usr/local/lib/python3.12/site-packages/django/db/backends/utils.py", line 80, in _execute_with_wrappers
    return executor(sql, params, many, context)
           ^^^^^^^^^^^^^^^^^^^^^^^^^^^^^^^^^^^^
  File "/usr/local/lib/python3.12/site-packages/django/db/backends/utils.py", line 84, in _execute
    with self.db.wrap_database_errors:
  File "/usr/local/lib/python3.12/site-packages/django/db/utils.py", line 91, in __exit__
    raise dj_exc_value.with_traceback(traceback) from exc_value
  File "/usr/local/lib/python3.12/site-packages/django/db/backends/utils.py", line 89, in _execute
    return self.cursor.execute(sql, params)
           ^^^^^^^^^^^^^^^^^^^^^^^^^^^^^^^^
django.db.utils.ProgrammingError: relation "auth_permission" does not exist
LINE 1: ...ntent_type_id", "auth_permission"."codename" FROM "auth_perm...
                                                             ^


During handling of the above exception, another exception occurred:

Traceback (most recent call last):
  File "/usr/local/lib/python3.12/site-packages/django/core/management/commands/dumpdata.py", line 265, in handle
    serializers.serialize(
  File "/usr/local/lib/python3.12/site-packages/django/core/serializers/__init__.py", line 134, in serialize
    s.serialize(queryset, **options)
  File "/usr/local/lib/python3.12/site-packages/django/core/serializers/base.py", line 132, in serialize
    for count, obj in enumerate(queryset, start=1):
  File "/usr/local/lib/python3.12/site-packages/django/core/management/commands/dumpdata.py", line 222, in get_objects
    yield from queryset.iterator()
  File "/usr/local/lib/python3.12/site-packages/django/db/models/query.py", line 516, in _iterator
    yield from iterable
  File "/usr/local/lib/python3.12/site-packages/django/db/models/query.py", line 91, in __iter__
    results = compiler.execute_sql(
              ^^^^^^^^^^^^^^^^^^^^^
  File "/usr/local/lib/python3.12/site-packages/django/db/models/sql/compiler.py", line 1565, in execute_sql
    cursor.close()
psycopg2.errors.InvalidCursorName: cursor "_django_curs_139708522707720_sync_1" does not exist


During handling of the above exception, another exception occurred:

Traceback (most recent call last):
  File "/usr/local/lib/python3.12/site-packages/celery/app/trace.py", line 477, in trace_task
    R = retval = fun(*args, **kwargs)
                 ^^^^^^^^^^^^^^^^^^^^
  File "/usr/local/lib/python3.12/site-packages/celery/app/trace.py", line 760, in __protected_call__
    return self.run(*args, **kwargs)
           ^^^^^^^^^^^^^^^^^^^^^^^^^
  File "/app/modules/services/tasks.py", line 30, in dbackup_task
    call_command('dbackup')
  File "/usr/local/lib/python3.12/site-packages/django/core/management/__init__.py", line 194, in call_command
    return command.execute(*args, **defaults)
           ^^^^^^^^^^^^^^^^^^^^^^^^^^^^^^^^^^
  File "/usr/local/lib/python3.12/site-packages/django/core/management/base.py", line 458, in execute
    output = self.handle(*args, **options)
             ^^^^^^^^^^^^^^^^^^^^^^^^^^^^^
  File "/app/modules/services/management/commands/dbackup.py", line 11, in handle
    call_command(
  File "/usr/local/lib/python3.12/site-packages/django/core/management/__init__.py", line 194, in call_command
    return command.execute(*args, **defaults)
           ^^^^^^^^^^^^^^^^^^^^^^^^^^^^^^^^^^
  File "/usr/local/lib/python3.12/site-packages/django/core/management/base.py", line 458, in execute
    output = self.handle(*args, **options)
             ^^^^^^^^^^^^^^^^^^^^^^^^^^^^^
  File "/usr/local/lib/python3.12/site-packages/django/core/management/commands/dumpdata.py", line 281, in handle
    raise CommandError("Unable to serialize database: %s" % e)
django.core.management.base.CommandError: Unable to serialize database: cursor "_django_curs_139708522707720_sync_1" does not exist

[2024-04-12 11:44:15,755: INFO/MainProcess] Task modules.services.tasks.send_activate_email_message_task[a046edd8-cb68-4be7-a3c7-fac053528a08] received
[2024-04-12 11:46:25,039: ERROR/ForkPoolWorker-1] Task modules.services.tasks.send_activate_email_message_task[a046edd8-cb68-4be7-a3c7-fac053528a08] raised unexpected: OSError(101, 'Network unreachable')
Traceback (most recent call last):
  File "/usr/local/lib/python3.12/site-packages/celery/app/trace.py", line 477, in trace_task
    R = retval = fun(*args, **kwargs)
                 ^^^^^^^^^^^^^^^^^^^^
  File "/usr/local/lib/python3.12/site-packages/celery/app/trace.py", line 760, in __protected_call__
    return self.run(*args, **kwargs)
           ^^^^^^^^^^^^^^^^^^^^^^^^^
  File "/app/modules/services/tasks.py", line 13, in send_activate_email_message_task
    return send_activate_email_message(user_id)
           ^^^^^^^^^^^^^^^^^^^^^^^^^^^^^^^^^^^^
  File "/app/modules/services/email.py", line 43, in send_activate_email_message
    return user.email_user(subject, message)
           ^^^^^^^^^^^^^^^^^^^^^^^^^^^^^^^^^
  File "/usr/local/lib/python3.12/site-packages/django/contrib/auth/models.py", line 402, in email_user
    send_mail(subject, message, from_email, [self.email], **kwargs)
  File "/usr/local/lib/python3.12/site-packages/django/core/mail/__init__.py", line 87, in send_mail
    return mail.send()
           ^^^^^^^^^^^
  File "/usr/local/lib/python3.12/site-packages/django/core/mail/message.py", line 298, in send
    return self.get_connection(fail_silently).send_messages([self])
           ^^^^^^^^^^^^^^^^^^^^^^^^^^^^^^^^^^^^^^^^^^^^^^^^^^^^^^^^
  File "/usr/local/lib/python3.12/site-packages/django/core/mail/backends/smtp.py", line 127, in send_messages
    new_conn_created = self.open()
                       ^^^^^^^^^^^
  File "/usr/local/lib/python3.12/site-packages/django/core/mail/backends/smtp.py", line 85, in open
    self.connection = self.connection_class(
                      ^^^^^^^^^^^^^^^^^^^^^^
  File "/usr/local/lib/python3.12/smtplib.py", line 255, in __init__
    (code, msg) = self.connect(host, port)
                  ^^^^^^^^^^^^^^^^^^^^^^^^
  File "/usr/local/lib/python3.12/smtplib.py", line 341, in connect
    self.sock = self._get_socket(host, port, self.timeout)
                ^^^^^^^^^^^^^^^^^^^^^^^^^^^^^^^^^^^^^^^^^^
  File "/usr/local/lib/python3.12/smtplib.py", line 312, in _get_socket
    return socket.create_connection((host, port), timeout,
           ^^^^^^^^^^^^^^^^^^^^^^^^^^^^^^^^^^^^^^^^^^^^^^^
  File "/usr/local/lib/python3.12/socket.py", line 852, in create_connection
    raise exceptions[0]
  File "/usr/local/lib/python3.12/socket.py", line 837, in create_connection
    sock.connect(sa)
OSError: [Errno 101] Network unreachable
[2024-04-12 12:17:37,787: INFO/MainProcess] Task modules.services.tasks.send_activate_email_message_task[e18c3079-3b48-4b7d-9b21-8d5ae813e3a6] received
[2024-04-12 12:19:47,982: ERROR/ForkPoolWorker-1] Task modules.services.tasks.send_activate_email_message_task[e18c3079-3b48-4b7d-9b21-8d5ae813e3a6] raised unexpected: OSError(101, 'Network unreachable')
Traceback (most recent call last):
  File "/usr/local/lib/python3.12/site-packages/celery/app/trace.py", line 477, in trace_task
    R = retval = fun(*args, **kwargs)
                 ^^^^^^^^^^^^^^^^^^^^
  File "/usr/local/lib/python3.12/site-packages/celery/app/trace.py", line 760, in __protected_call__
    return self.run(*args, **kwargs)
           ^^^^^^^^^^^^^^^^^^^^^^^^^
  File "/app/modules/services/tasks.py", line 13, in send_activate_email_message_task
    return send_activate_email_message(user_id)
           ^^^^^^^^^^^^^^^^^^^^^^^^^^^^^^^^^^^^
  File "/app/modules/services/email.py", line 43, in send_activate_email_message
    return user.email_user(subject, message)
           ^^^^^^^^^^^^^^^^^^^^^^^^^^^^^^^^^
  File "/usr/local/lib/python3.12/site-packages/django/contrib/auth/models.py", line 402, in email_user
    send_mail(subject, message, from_email, [self.email], **kwargs)
  File "/usr/local/lib/python3.12/site-packages/django/core/mail/__init__.py", line 87, in send_mail
    return mail.send()
           ^^^^^^^^^^^
  File "/usr/local/lib/python3.12/site-packages/django/core/mail/message.py", line 298, in send
    return self.get_connection(fail_silently).send_messages([self])
           ^^^^^^^^^^^^^^^^^^^^^^^^^^^^^^^^^^^^^^^^^^^^^^^^^^^^^^^^
  File "/usr/local/lib/python3.12/site-packages/django/core/mail/backends/smtp.py", line 127, in send_messages
    new_conn_created = self.open()
                       ^^^^^^^^^^^
  File "/usr/local/lib/python3.12/site-packages/django/core/mail/backends/smtp.py", line 85, in open
    self.connection = self.connection_class(
                      ^^^^^^^^^^^^^^^^^^^^^^
  File "/usr/local/lib/python3.12/smtplib.py", line 255, in __init__
    (code, msg) = self.connect(host, port)
                  ^^^^^^^^^^^^^^^^^^^^^^^^
  File "/usr/local/lib/python3.12/smtplib.py", line 341, in connect
    self.sock = self._get_socket(host, port, self.timeout)
                ^^^^^^^^^^^^^^^^^^^^^^^^^^^^^^^^^^^^^^^^^^
  File "/usr/local/lib/python3.12/smtplib.py", line 312, in _get_socket
    return socket.create_connection((host, port), timeout,
           ^^^^^^^^^^^^^^^^^^^^^^^^^^^^^^^^^^^^^^^^^^^^^^^
  File "/usr/local/lib/python3.12/socket.py", line 852, in create_connection
    raise exceptions[0]
  File "/usr/local/lib/python3.12/socket.py", line 837, in create_connection
    sock.connect(sa)
OSError: [Errno 101] Network unreachable
[2024-04-12 12:32:17,487: INFO/MainProcess] Task modules.services.tasks.send_activate_email_message_task[aa0fc1cc-a107-49a4-892b-d67a145fb444] received
[2024-04-12 12:34:28,619: ERROR/ForkPoolWorker-1] Task modules.services.tasks.send_activate_email_message_task[aa0fc1cc-a107-49a4-892b-d67a145fb444] raised unexpected: OSError(101, 'Network unreachable')
Traceback (most recent call last):
  File "/usr/local/lib/python3.12/site-packages/celery/app/trace.py", line 477, in trace_task
    R = retval = fun(*args, **kwargs)
                 ^^^^^^^^^^^^^^^^^^^^
  File "/usr/local/lib/python3.12/site-packages/celery/app/trace.py", line 760, in __protected_call__
    return self.run(*args, **kwargs)
           ^^^^^^^^^^^^^^^^^^^^^^^^^
  File "/app/modules/services/tasks.py", line 13, in send_activate_email_message_task
    return send_activate_email_message(user_id)
           ^^^^^^^^^^^^^^^^^^^^^^^^^^^^^^^^^^^^
  File "/app/modules/services/email.py", line 43, in send_activate_email_message
    return user.email_user(subject, message)
           ^^^^^^^^^^^^^^^^^^^^^^^^^^^^^^^^^
  File "/usr/local/lib/python3.12/site-packages/django/contrib/auth/models.py", line 402, in email_user
    send_mail(subject, message, from_email, [self.email], **kwargs)
  File "/usr/local/lib/python3.12/site-packages/django/core/mail/__init__.py", line 87, in send_mail
    return mail.send()
           ^^^^^^^^^^^
  File "/usr/local/lib/python3.12/site-packages/django/core/mail/message.py", line 298, in send
    return self.get_connection(fail_silently).send_messages([self])
           ^^^^^^^^^^^^^^^^^^^^^^^^^^^^^^^^^^^^^^^^^^^^^^^^^^^^^^^^
  File "/usr/local/lib/python3.12/site-packages/django/core/mail/backends/smtp.py", line 127, in send_messages
    new_conn_created = self.open()
                       ^^^^^^^^^^^
  File "/usr/local/lib/python3.12/site-packages/django/core/mail/backends/smtp.py", line 85, in open
    self.connection = self.connection_class(
                      ^^^^^^^^^^^^^^^^^^^^^^
  File "/usr/local/lib/python3.12/smtplib.py", line 255, in __init__
    (code, msg) = self.connect(host, port)
                  ^^^^^^^^^^^^^^^^^^^^^^^^
  File "/usr/local/lib/python3.12/smtplib.py", line 341, in connect
    self.sock = self._get_socket(host, port, self.timeout)
                ^^^^^^^^^^^^^^^^^^^^^^^^^^^^^^^^^^^^^^^^^^
  File "/usr/local/lib/python3.12/smtplib.py", line 312, in _get_socket
    return socket.create_connection((host, port), timeout,
           ^^^^^^^^^^^^^^^^^^^^^^^^^^^^^^^^^^^^^^^^^^^^^^^
  File "/usr/local/lib/python3.12/socket.py", line 852, in create_connection
    raise exceptions[0]
  File "/usr/local/lib/python3.12/socket.py", line 837, in create_connection
    sock.connect(sa)
OSError: [Errno 101] Network unreachable
[2024-04-12 12:37:35,353: WARNING/MainProcess] /usr/local/lib/python3.12/site-packages/celery/worker/consumer/consumer.py:507: CPendingDeprecationWarning: The broker_connection_retry configuration setting will no longer determine
whether broker connection retries are made during startup in Celery 6.0 and above.
If you wish to retain the existing behavior for retrying connections on startup,
you should set broker_connection_retry_on_startup to True.
  warnings.warn(

[2024-04-12 12:37:35,405: INFO/MainProcess] Connected to redis://redis:6379/0
[2024-04-12 12:37:35,407: WARNING/MainProcess] /usr/local/lib/python3.12/site-packages/celery/worker/consumer/consumer.py:507: CPendingDeprecationWarning: The broker_connection_retry configuration setting will no longer determine
whether broker connection retries are made during startup in Celery 6.0 and above.
If you wish to retain the existing behavior for retrying connections on startup,
you should set broker_connection_retry_on_startup to True.
  warnings.warn(

[2024-04-12 12:37:35,414: INFO/MainProcess] mingle: searching for neighbors
[2024-04-12 12:37:36,433: INFO/MainProcess] mingle: all alone
[2024-04-12 12:37:36,461: INFO/MainProcess] celery@059f17bd8774 ready.
[2024-04-12 12:39:11,680: INFO/MainProcess] Task modules.services.tasks.send_activate_email_message_task[25972873-7971-419f-85f5-b11cc8c577fb] received
[2024-04-12 12:41:22,330: ERROR/ForkPoolWorker-1] Task modules.services.tasks.send_activate_email_message_task[25972873-7971-419f-85f5-b11cc8c577fb] raised unexpected: OSError(101, 'Network unreachable')
Traceback (most recent call last):
  File "/usr/local/lib/python3.12/site-packages/celery/app/trace.py", line 477, in trace_task
    R = retval = fun(*args, **kwargs)
                 ^^^^^^^^^^^^^^^^^^^^
  File "/usr/local/lib/python3.12/site-packages/celery/app/trace.py", line 760, in __protected_call__
    return self.run(*args, **kwargs)
           ^^^^^^^^^^^^^^^^^^^^^^^^^
  File "/app/modules/services/tasks.py", line 13, in send_activate_email_message_task
    return send_activate_email_message(user_id)
           ^^^^^^^^^^^^^^^^^^^^^^^^^^^^^^^^^^^^
  File "/app/modules/services/email.py", line 43, in send_activate_email_message
    return user.email_user(subject, message)
           ^^^^^^^^^^^^^^^^^^^^^^^^^^^^^^^^^
  File "/usr/local/lib/python3.12/site-packages/django/contrib/auth/models.py", line 402, in email_user
    send_mail(subject, message, from_email, [self.email], **kwargs)
  File "/usr/local/lib/python3.12/site-packages/django/core/mail/__init__.py", line 87, in send_mail
    return mail.send()
           ^^^^^^^^^^^
  File "/usr/local/lib/python3.12/site-packages/django/core/mail/message.py", line 298, in send
    return self.get_connection(fail_silently).send_messages([self])
           ^^^^^^^^^^^^^^^^^^^^^^^^^^^^^^^^^^^^^^^^^^^^^^^^^^^^^^^^
  File "/usr/local/lib/python3.12/site-packages/django/core/mail/backends/smtp.py", line 127, in send_messages
    new_conn_created = self.open()
                       ^^^^^^^^^^^
  File "/usr/local/lib/python3.12/site-packages/django/core/mail/backends/smtp.py", line 85, in open
    self.connection = self.connection_class(
                      ^^^^^^^^^^^^^^^^^^^^^^
  File "/usr/local/lib/python3.12/smtplib.py", line 255, in __init__
    (code, msg) = self.connect(host, port)
                  ^^^^^^^^^^^^^^^^^^^^^^^^
  File "/usr/local/lib/python3.12/smtplib.py", line 341, in connect
    self.sock = self._get_socket(host, port, self.timeout)
                ^^^^^^^^^^^^^^^^^^^^^^^^^^^^^^^^^^^^^^^^^^
  File "/usr/local/lib/python3.12/smtplib.py", line 312, in _get_socket
    return socket.create_connection((host, port), timeout,
           ^^^^^^^^^^^^^^^^^^^^^^^^^^^^^^^^^^^^^^^^^^^^^^^
  File "/usr/local/lib/python3.12/socket.py", line 852, in create_connection
    raise exceptions[0]
  File "/usr/local/lib/python3.12/socket.py", line 837, in create_connection
    sock.connect(sa)
OSError: [Errno 101] Network unreachable
[2024-04-12 13:00:27,906: WARNING/MainProcess] /usr/local/lib/python3.12/site-packages/celery/worker/consumer/consumer.py:507: CPendingDeprecationWarning: The broker_connection_retry configuration setting will no longer determine
whether broker connection retries are made during startup in Celery 6.0 and above.
If you wish to retain the existing behavior for retrying connections on startup,
you should set broker_connection_retry_on_startup to True.
  warnings.warn(

[2024-04-12 13:00:27,959: INFO/MainProcess] Connected to redis://redis:6379/0
[2024-04-12 13:00:27,964: WARNING/MainProcess] /usr/local/lib/python3.12/site-packages/celery/worker/consumer/consumer.py:507: CPendingDeprecationWarning: The broker_connection_retry configuration setting will no longer determine
whether broker connection retries are made during startup in Celery 6.0 and above.
If you wish to retain the existing behavior for retrying connections on startup,
you should set broker_connection_retry_on_startup to True.
  warnings.warn(

[2024-04-12 13:00:27,973: INFO/MainProcess] mingle: searching for neighbors
[2024-04-12 13:00:28,995: INFO/MainProcess] mingle: all alone
[2024-04-12 13:00:29,026: INFO/MainProcess] celery@71fec6efe652 ready.
[2024-04-12 13:01:50,242: INFO/MainProcess] Task modules.services.tasks.send_activate_email_message_task[548cea61-7a5a-4915-adf9-6e669084af57] received
[2024-04-12 13:04:00,147: ERROR/ForkPoolWorker-1] Task modules.services.tasks.send_activate_email_message_task[548cea61-7a5a-4915-adf9-6e669084af57] raised unexpected: OSError(101, 'Network unreachable')
Traceback (most recent call last):
  File "/usr/local/lib/python3.12/site-packages/celery/app/trace.py", line 477, in trace_task
    R = retval = fun(*args, **kwargs)
                 ^^^^^^^^^^^^^^^^^^^^
  File "/usr/local/lib/python3.12/site-packages/celery/app/trace.py", line 760, in __protected_call__
    return self.run(*args, **kwargs)
           ^^^^^^^^^^^^^^^^^^^^^^^^^
  File "/app/modules/services/tasks.py", line 13, in send_activate_email_message_task
    return send_activate_email_message(user_id)
           ^^^^^^^^^^^^^^^^^^^^^^^^^^^^^^^^^^^^
  File "/app/modules/services/email.py", line 43, in send_activate_email_message
    return user.email_user(subject, message)
           ^^^^^^^^^^^^^^^^^^^^^^^^^^^^^^^^^
  File "/usr/local/lib/python3.12/site-packages/django/contrib/auth/models.py", line 402, in email_user
    send_mail(subject, message, from_email, [self.email], **kwargs)
  File "/usr/local/lib/python3.12/site-packages/django/core/mail/__init__.py", line 87, in send_mail
    return mail.send()
           ^^^^^^^^^^^
  File "/usr/local/lib/python3.12/site-packages/django/core/mail/message.py", line 298, in send
    return self.get_connection(fail_silently).send_messages([self])
           ^^^^^^^^^^^^^^^^^^^^^^^^^^^^^^^^^^^^^^^^^^^^^^^^^^^^^^^^
  File "/usr/local/lib/python3.12/site-packages/django/core/mail/backends/smtp.py", line 127, in send_messages
    new_conn_created = self.open()
                       ^^^^^^^^^^^
  File "/usr/local/lib/python3.12/site-packages/django/core/mail/backends/smtp.py", line 85, in open
    self.connection = self.connection_class(
                      ^^^^^^^^^^^^^^^^^^^^^^
  File "/usr/local/lib/python3.12/smtplib.py", line 255, in __init__
    (code, msg) = self.connect(host, port)
                  ^^^^^^^^^^^^^^^^^^^^^^^^
  File "/usr/local/lib/python3.12/smtplib.py", line 341, in connect
    self.sock = self._get_socket(host, port, self.timeout)
                ^^^^^^^^^^^^^^^^^^^^^^^^^^^^^^^^^^^^^^^^^^
  File "/usr/local/lib/python3.12/smtplib.py", line 312, in _get_socket
    return socket.create_connection((host, port), timeout,
           ^^^^^^^^^^^^^^^^^^^^^^^^^^^^^^^^^^^^^^^^^^^^^^^
  File "/usr/local/lib/python3.12/socket.py", line 852, in create_connection
    raise exceptions[0]
  File "/usr/local/lib/python3.12/socket.py", line 837, in create_connection
    sock.connect(sa)
OSError: [Errno 101] Network unreachable
[2024-04-12 13:04:25,998: INFO/MainProcess] Task modules.services.tasks.send_activate_email_message_task[151af093-6819-410b-9317-45c8537ac3b9] received
[2024-04-12 13:06:35,792: ERROR/ForkPoolWorker-1] Task modules.services.tasks.send_activate_email_message_task[151af093-6819-410b-9317-45c8537ac3b9] raised unexpected: OSError(101, 'Network unreachable')
Traceback (most recent call last):
  File "/usr/local/lib/python3.12/site-packages/celery/app/trace.py", line 477, in trace_task
    R = retval = fun(*args, **kwargs)
                 ^^^^^^^^^^^^^^^^^^^^
  File "/usr/local/lib/python3.12/site-packages/celery/app/trace.py", line 760, in __protected_call__
    return self.run(*args, **kwargs)
           ^^^^^^^^^^^^^^^^^^^^^^^^^
  File "/app/modules/services/tasks.py", line 13, in send_activate_email_message_task
    return send_activate_email_message(user_id)
           ^^^^^^^^^^^^^^^^^^^^^^^^^^^^^^^^^^^^
  File "/app/modules/services/email.py", line 43, in send_activate_email_message
    return user.email_user(subject, message)
           ^^^^^^^^^^^^^^^^^^^^^^^^^^^^^^^^^
  File "/usr/local/lib/python3.12/site-packages/django/contrib/auth/models.py", line 402, in email_user
    send_mail(subject, message, from_email, [self.email], **kwargs)
  File "/usr/local/lib/python3.12/site-packages/django/core/mail/__init__.py", line 87, in send_mail
    return mail.send()
           ^^^^^^^^^^^
  File "/usr/local/lib/python3.12/site-packages/django/core/mail/message.py", line 298, in send
    return self.get_connection(fail_silently).send_messages([self])
           ^^^^^^^^^^^^^^^^^^^^^^^^^^^^^^^^^^^^^^^^^^^^^^^^^^^^^^^^
  File "/usr/local/lib/python3.12/site-packages/django/core/mail/backends/smtp.py", line 127, in send_messages
    new_conn_created = self.open()
                       ^^^^^^^^^^^
  File "/usr/local/lib/python3.12/site-packages/django/core/mail/backends/smtp.py", line 85, in open
    self.connection = self.connection_class(
                      ^^^^^^^^^^^^^^^^^^^^^^
  File "/usr/local/lib/python3.12/smtplib.py", line 255, in __init__
    (code, msg) = self.connect(host, port)
                  ^^^^^^^^^^^^^^^^^^^^^^^^
  File "/usr/local/lib/python3.12/smtplib.py", line 341, in connect
    self.sock = self._get_socket(host, port, self.timeout)
                ^^^^^^^^^^^^^^^^^^^^^^^^^^^^^^^^^^^^^^^^^^
  File "/usr/local/lib/python3.12/smtplib.py", line 312, in _get_socket
    return socket.create_connection((host, port), timeout,
           ^^^^^^^^^^^^^^^^^^^^^^^^^^^^^^^^^^^^^^^^^^^^^^^
  File "/usr/local/lib/python3.12/socket.py", line 852, in create_connection
    raise exceptions[0]
  File "/usr/local/lib/python3.12/socket.py", line 837, in create_connection
    sock.connect(sa)
OSError: [Errno 101] Network unreachable
[2024-04-12 13:08:51,777: WARNING/MainProcess] /usr/local/lib/python3.12/site-packages/celery/worker/consumer/consumer.py:507: CPendingDeprecationWarning: The broker_connection_retry configuration setting will no longer determine
whether broker connection retries are made during startup in Celery 6.0 and above.
If you wish to retain the existing behavior for retrying connections on startup,
you should set broker_connection_retry_on_startup to True.
  warnings.warn(

[2024-04-12 13:08:51,838: INFO/MainProcess] Connected to redis://redis:6379/0
[2024-04-12 13:08:51,839: WARNING/MainProcess] /usr/local/lib/python3.12/site-packages/celery/worker/consumer/consumer.py:507: CPendingDeprecationWarning: The broker_connection_retry configuration setting will no longer determine
whether broker connection retries are made during startup in Celery 6.0 and above.
If you wish to retain the existing behavior for retrying connections on startup,
you should set broker_connection_retry_on_startup to True.
  warnings.warn(

[2024-04-12 13:08:51,843: INFO/MainProcess] mingle: searching for neighbors
[2024-04-12 13:08:52,867: INFO/MainProcess] mingle: all alone
[2024-04-12 13:08:52,905: INFO/MainProcess] celery@7bf760a217e1 ready.
[2024-04-12 13:10:10,097: WARNING/MainProcess] /usr/local/lib/python3.12/site-packages/celery/worker/consumer/consumer.py:507: CPendingDeprecationWarning: The broker_connection_retry configuration setting will no longer determine
whether broker connection retries are made during startup in Celery 6.0 and above.
If you wish to retain the existing behavior for retrying connections on startup,
you should set broker_connection_retry_on_startup to True.
  warnings.warn(

[2024-04-12 13:10:10,152: INFO/MainProcess] Connected to redis://redis:6379/0
[2024-04-12 13:10:10,155: WARNING/MainProcess] /usr/local/lib/python3.12/site-packages/celery/worker/consumer/consumer.py:507: CPendingDeprecationWarning: The broker_connection_retry configuration setting will no longer determine
whether broker connection retries are made during startup in Celery 6.0 and above.
If you wish to retain the existing behavior for retrying connections on startup,
you should set broker_connection_retry_on_startup to True.
  warnings.warn(

[2024-04-12 13:10:10,166: INFO/MainProcess] mingle: searching for neighbors
[2024-04-12 13:10:11,185: INFO/MainProcess] mingle: all alone
[2024-04-12 13:10:11,214: INFO/MainProcess] celery@89ab15eedd3e ready.
[2024-04-12 13:10:39,999: INFO/MainProcess] Task modules.services.tasks.send_activate_email_message_task[3b2c4e65-55a7-472d-b14a-c65852002cee] received
[2024-04-12 13:12:50,577: ERROR/ForkPoolWorker-1] Task modules.services.tasks.send_activate_email_message_task[3b2c4e65-55a7-472d-b14a-c65852002cee] raised unexpected: OSError(101, 'Network unreachable')
Traceback (most recent call last):
  File "/usr/local/lib/python3.12/site-packages/celery/app/trace.py", line 477, in trace_task
    R = retval = fun(*args, **kwargs)
                 ^^^^^^^^^^^^^^^^^^^^
  File "/usr/local/lib/python3.12/site-packages/celery/app/trace.py", line 760, in __protected_call__
    return self.run(*args, **kwargs)
           ^^^^^^^^^^^^^^^^^^^^^^^^^
  File "/app/modules/services/tasks.py", line 13, in send_activate_email_message_task
    return send_activate_email_message(user_id)
           ^^^^^^^^^^^^^^^^^^^^^^^^^^^^^^^^^^^^
  File "/app/modules/services/email.py", line 43, in send_activate_email_message
    return user.email_user(subject, message)
           ^^^^^^^^^^^^^^^^^^^^^^^^^^^^^^^^^
  File "/usr/local/lib/python3.12/site-packages/django/contrib/auth/models.py", line 402, in email_user
    send_mail(subject, message, from_email, [self.email], **kwargs)
  File "/usr/local/lib/python3.12/site-packages/django/core/mail/__init__.py", line 87, in send_mail
    return mail.send()
           ^^^^^^^^^^^
  File "/usr/local/lib/python3.12/site-packages/django/core/mail/message.py", line 298, in send
    return self.get_connection(fail_silently).send_messages([self])
           ^^^^^^^^^^^^^^^^^^^^^^^^^^^^^^^^^^^^^^^^^^^^^^^^^^^^^^^^
  File "/usr/local/lib/python3.12/site-packages/django/core/mail/backends/smtp.py", line 127, in send_messages
    new_conn_created = self.open()
                       ^^^^^^^^^^^
  File "/usr/local/lib/python3.12/site-packages/django/core/mail/backends/smtp.py", line 85, in open
    self.connection = self.connection_class(
                      ^^^^^^^^^^^^^^^^^^^^^^
  File "/usr/local/lib/python3.12/smtplib.py", line 255, in __init__
    (code, msg) = self.connect(host, port)
                  ^^^^^^^^^^^^^^^^^^^^^^^^
  File "/usr/local/lib/python3.12/smtplib.py", line 341, in connect
    self.sock = self._get_socket(host, port, self.timeout)
                ^^^^^^^^^^^^^^^^^^^^^^^^^^^^^^^^^^^^^^^^^^
  File "/usr/local/lib/python3.12/smtplib.py", line 312, in _get_socket
    return socket.create_connection((host, port), timeout,
           ^^^^^^^^^^^^^^^^^^^^^^^^^^^^^^^^^^^^^^^^^^^^^^^
  File "/usr/local/lib/python3.12/socket.py", line 852, in create_connection
    raise exceptions[0]
  File "/usr/local/lib/python3.12/socket.py", line 837, in create_connection
    sock.connect(sa)
OSError: [Errno 101] Network unreachable
[2024-04-12 13:15:34,406: WARNING/MainProcess] /usr/local/lib/python3.12/site-packages/celery/worker/consumer/consumer.py:507: CPendingDeprecationWarning: The broker_connection_retry configuration setting will no longer determine
whether broker connection retries are made during startup in Celery 6.0 and above.
If you wish to retain the existing behavior for retrying connections on startup,
you should set broker_connection_retry_on_startup to True.
  warnings.warn(

[2024-04-12 13:15:34,461: INFO/MainProcess] Connected to redis://redis:6379/0
[2024-04-12 13:15:34,463: WARNING/MainProcess] /usr/local/lib/python3.12/site-packages/celery/worker/consumer/consumer.py:507: CPendingDeprecationWarning: The broker_connection_retry configuration setting will no longer determine
whether broker connection retries are made during startup in Celery 6.0 and above.
If you wish to retain the existing behavior for retrying connections on startup,
you should set broker_connection_retry_on_startup to True.
  warnings.warn(

[2024-04-12 13:15:34,470: INFO/MainProcess] mingle: searching for neighbors
[2024-04-12 13:15:35,491: INFO/MainProcess] mingle: all alone
[2024-04-12 13:15:35,525: INFO/MainProcess] celery@89ab15eedd3e ready.
[2024-04-12 13:16:43,377: WARNING/MainProcess] /usr/local/lib/python3.12/site-packages/celery/worker/consumer/consumer.py:507: CPendingDeprecationWarning: The broker_connection_retry configuration setting will no longer determine
whether broker connection retries are made during startup in Celery 6.0 and above.
If you wish to retain the existing behavior for retrying connections on startup,
you should set broker_connection_retry_on_startup to True.
  warnings.warn(

[2024-04-12 13:16:43,431: INFO/MainProcess] Connected to redis://redis:6379/0
[2024-04-12 13:16:43,433: WARNING/MainProcess] /usr/local/lib/python3.12/site-packages/celery/worker/consumer/consumer.py:507: CPendingDeprecationWarning: The broker_connection_retry configuration setting will no longer determine
whether broker connection retries are made during startup in Celery 6.0 and above.
If you wish to retain the existing behavior for retrying connections on startup,
you should set broker_connection_retry_on_startup to True.
  warnings.warn(

[2024-04-12 13:16:43,437: INFO/MainProcess] mingle: searching for neighbors
[2024-04-12 13:16:44,458: INFO/MainProcess] mingle: all alone
[2024-04-12 13:16:44,491: INFO/MainProcess] celery@89ab15eedd3e ready.
[2024-04-12 13:18:02,821: WARNING/MainProcess] /usr/local/lib/python3.12/site-packages/celery/worker/consumer/consumer.py:507: CPendingDeprecationWarning: The broker_connection_retry configuration setting will no longer determine
whether broker connection retries are made during startup in Celery 6.0 and above.
If you wish to retain the existing behavior for retrying connections on startup,
you should set broker_connection_retry_on_startup to True.
  warnings.warn(

[2024-04-12 13:18:02,882: INFO/MainProcess] Connected to redis://redis:6379/0
[2024-04-12 13:18:02,883: WARNING/MainProcess] /usr/local/lib/python3.12/site-packages/celery/worker/consumer/consumer.py:507: CPendingDeprecationWarning: The broker_connection_retry configuration setting will no longer determine
whether broker connection retries are made during startup in Celery 6.0 and above.
If you wish to retain the existing behavior for retrying connections on startup,
you should set broker_connection_retry_on_startup to True.
  warnings.warn(

[2024-04-12 13:18:02,898: INFO/MainProcess] mingle: searching for neighbors
[2024-04-12 13:18:03,926: INFO/MainProcess] mingle: all alone
[2024-04-12 13:18:03,953: INFO/MainProcess] celery@752eb584d1b5 ready.
[2024-04-12 13:18:34,959: INFO/MainProcess] Task modules.services.tasks.send_activate_email_message_task[e7596f54-6225-465f-8b6f-9bd91c425bf6] received
[2024-04-12 13:19:32,276: WARNING/MainProcess] /usr/local/lib/python3.12/site-packages/celery/worker/consumer/consumer.py:507: CPendingDeprecationWarning: The broker_connection_retry configuration setting will no longer determine
whether broker connection retries are made during startup in Celery 6.0 and above.
If you wish to retain the existing behavior for retrying connections on startup,
you should set broker_connection_retry_on_startup to True.
  warnings.warn(

[2024-04-12 13:19:32,326: INFO/MainProcess] Connected to redis://redis:6379/0
[2024-04-12 13:19:32,327: WARNING/MainProcess] /usr/local/lib/python3.12/site-packages/celery/worker/consumer/consumer.py:507: CPendingDeprecationWarning: The broker_connection_retry configuration setting will no longer determine
whether broker connection retries are made during startup in Celery 6.0 and above.
If you wish to retain the existing behavior for retrying connections on startup,
you should set broker_connection_retry_on_startup to True.
  warnings.warn(

[2024-04-12 13:19:32,332: INFO/MainProcess] mingle: searching for neighbors
[2024-04-12 13:19:33,355: INFO/MainProcess] mingle: all alone
[2024-04-12 13:19:33,384: INFO/MainProcess] celery@3a3ad7c54731 ready.
[2024-04-12 13:20:09,172: INFO/MainProcess] Task modules.services.tasks.send_activate_email_message_task[5eab4172-80ed-4ef3-b564-456479542300] received
[2024-04-12 13:22:19,918: ERROR/ForkPoolWorker-1] Task modules.services.tasks.send_activate_email_message_task[5eab4172-80ed-4ef3-b564-456479542300] raised unexpected: OSError(101, 'Network unreachable')
Traceback (most recent call last):
  File "/usr/local/lib/python3.12/site-packages/celery/app/trace.py", line 477, in trace_task
    R = retval = fun(*args, **kwargs)
                 ^^^^^^^^^^^^^^^^^^^^
  File "/usr/local/lib/python3.12/site-packages/celery/app/trace.py", line 760, in __protected_call__
    return self.run(*args, **kwargs)
           ^^^^^^^^^^^^^^^^^^^^^^^^^
  File "/app/modules/services/tasks.py", line 13, in send_activate_email_message_task
    return send_activate_email_message(user_id)
           ^^^^^^^^^^^^^^^^^^^^^^^^^^^^^^^^^^^^
  File "/app/modules/services/email.py", line 43, in send_activate_email_message
    return user.email_user(subject, message)
           ^^^^^^^^^^^^^^^^^^^^^^^^^^^^^^^^^
  File "/usr/local/lib/python3.12/site-packages/django/contrib/auth/models.py", line 402, in email_user
    send_mail(subject, message, from_email, [self.email], **kwargs)
  File "/usr/local/lib/python3.12/site-packages/django/core/mail/__init__.py", line 87, in send_mail
    return mail.send()
           ^^^^^^^^^^^
  File "/usr/local/lib/python3.12/site-packages/django/core/mail/message.py", line 298, in send
    return self.get_connection(fail_silently).send_messages([self])
           ^^^^^^^^^^^^^^^^^^^^^^^^^^^^^^^^^^^^^^^^^^^^^^^^^^^^^^^^
  File "/usr/local/lib/python3.12/site-packages/django/core/mail/backends/smtp.py", line 127, in send_messages
    new_conn_created = self.open()
                       ^^^^^^^^^^^
  File "/usr/local/lib/python3.12/site-packages/django/core/mail/backends/smtp.py", line 85, in open
    self.connection = self.connection_class(
                      ^^^^^^^^^^^^^^^^^^^^^^
  File "/usr/local/lib/python3.12/smtplib.py", line 255, in __init__
    (code, msg) = self.connect(host, port)
                  ^^^^^^^^^^^^^^^^^^^^^^^^
  File "/usr/local/lib/python3.12/smtplib.py", line 341, in connect
    self.sock = self._get_socket(host, port, self.timeout)
                ^^^^^^^^^^^^^^^^^^^^^^^^^^^^^^^^^^^^^^^^^^
  File "/usr/local/lib/python3.12/smtplib.py", line 312, in _get_socket
    return socket.create_connection((host, port), timeout,
           ^^^^^^^^^^^^^^^^^^^^^^^^^^^^^^^^^^^^^^^^^^^^^^^
  File "/usr/local/lib/python3.12/socket.py", line 852, in create_connection
    raise exceptions[0]
  File "/usr/local/lib/python3.12/socket.py", line 837, in create_connection
    sock.connect(sa)
OSError: [Errno 101] Network unreachable
[2024-04-12 13:32:14,343: INFO/MainProcess] Task modules.services.tasks.send_activate_email_message_task[624df740-81eb-4026-9f40-0c57e0546f10] received
[2024-04-12 13:33:10,596: WARNING/MainProcess] /usr/local/lib/python3.12/site-packages/celery/worker/consumer/consumer.py:507: CPendingDeprecationWarning: The broker_connection_retry configuration setting will no longer determine
whether broker connection retries are made during startup in Celery 6.0 and above.
If you wish to retain the existing behavior for retrying connections on startup,
you should set broker_connection_retry_on_startup to True.
  warnings.warn(

[2024-04-12 13:33:10,659: INFO/MainProcess] Connected to redis://redis:6379/0
[2024-04-12 13:33:10,661: WARNING/MainProcess] /usr/local/lib/python3.12/site-packages/celery/worker/consumer/consumer.py:507: CPendingDeprecationWarning: The broker_connection_retry configuration setting will no longer determine
whether broker connection retries are made during startup in Celery 6.0 and above.
If you wish to retain the existing behavior for retrying connections on startup,
you should set broker_connection_retry_on_startup to True.
  warnings.warn(

[2024-04-12 13:33:10,671: INFO/MainProcess] mingle: searching for neighbors
[2024-04-12 13:33:11,691: INFO/MainProcess] mingle: all alone
[2024-04-12 13:33:11,729: INFO/MainProcess] celery@ab4b544b2272 ready.
[2024-04-12 13:33:48,619: INFO/MainProcess] Task modules.services.tasks.send_activate_email_message_task[ca049e18-df84-4343-900b-c8c8b4f14751] received
[2024-04-12 13:35:59,122: ERROR/ForkPoolWorker-1] Task modules.services.tasks.send_activate_email_message_task[ca049e18-df84-4343-900b-c8c8b4f14751] raised unexpected: OSError(101, 'Network unreachable')
Traceback (most recent call last):
  File "/usr/local/lib/python3.12/site-packages/celery/app/trace.py", line 477, in trace_task
    R = retval = fun(*args, **kwargs)
                 ^^^^^^^^^^^^^^^^^^^^
  File "/usr/local/lib/python3.12/site-packages/celery/app/trace.py", line 760, in __protected_call__
    return self.run(*args, **kwargs)
           ^^^^^^^^^^^^^^^^^^^^^^^^^
  File "/app/modules/services/tasks.py", line 13, in send_activate_email_message_task
    return send_activate_email_message(user_id)
           ^^^^^^^^^^^^^^^^^^^^^^^^^^^^^^^^^^^^
  File "/app/modules/services/email.py", line 43, in send_activate_email_message
    return user.email_user(subject, message)
           ^^^^^^^^^^^^^^^^^^^^^^^^^^^^^^^^^
  File "/usr/local/lib/python3.12/site-packages/django/contrib/auth/models.py", line 402, in email_user
    send_mail(subject, message, from_email, [self.email], **kwargs)
  File "/usr/local/lib/python3.12/site-packages/django/core/mail/__init__.py", line 87, in send_mail
    return mail.send()
           ^^^^^^^^^^^
  File "/usr/local/lib/python3.12/site-packages/django/core/mail/message.py", line 298, in send
    return self.get_connection(fail_silently).send_messages([self])
           ^^^^^^^^^^^^^^^^^^^^^^^^^^^^^^^^^^^^^^^^^^^^^^^^^^^^^^^^
  File "/usr/local/lib/python3.12/site-packages/django/core/mail/backends/smtp.py", line 127, in send_messages
    new_conn_created = self.open()
                       ^^^^^^^^^^^
  File "/usr/local/lib/python3.12/site-packages/django/core/mail/backends/smtp.py", line 85, in open
    self.connection = self.connection_class(
                      ^^^^^^^^^^^^^^^^^^^^^^
  File "/usr/local/lib/python3.12/smtplib.py", line 255, in __init__
    (code, msg) = self.connect(host, port)
                  ^^^^^^^^^^^^^^^^^^^^^^^^
  File "/usr/local/lib/python3.12/smtplib.py", line 341, in connect
    self.sock = self._get_socket(host, port, self.timeout)
                ^^^^^^^^^^^^^^^^^^^^^^^^^^^^^^^^^^^^^^^^^^
  File "/usr/local/lib/python3.12/smtplib.py", line 312, in _get_socket
    return socket.create_connection((host, port), timeout,
           ^^^^^^^^^^^^^^^^^^^^^^^^^^^^^^^^^^^^^^^^^^^^^^^
  File "/usr/local/lib/python3.12/socket.py", line 852, in create_connection
    raise exceptions[0]
  File "/usr/local/lib/python3.12/socket.py", line 837, in create_connection
    sock.connect(sa)
OSError: [Errno 101] Network unreachable
[2024-04-12 13:36:12,664: WARNING/MainProcess] /usr/local/lib/python3.12/site-packages/celery/worker/consumer/consumer.py:507: CPendingDeprecationWarning: The broker_connection_retry configuration setting will no longer determine
whether broker connection retries are made during startup in Celery 6.0 and above.
If you wish to retain the existing behavior for retrying connections on startup,
you should set broker_connection_retry_on_startup to True.
  warnings.warn(

[2024-04-12 13:36:12,694: INFO/MainProcess] Connected to redis://redis:6379/0
[2024-04-12 13:36:12,695: WARNING/MainProcess] /usr/local/lib/python3.12/site-packages/celery/worker/consumer/consumer.py:507: CPendingDeprecationWarning: The broker_connection_retry configuration setting will no longer determine
whether broker connection retries are made during startup in Celery 6.0 and above.
If you wish to retain the existing behavior for retrying connections on startup,
you should set broker_connection_retry_on_startup to True.
  warnings.warn(

[2024-04-12 13:36:12,698: INFO/MainProcess] mingle: searching for neighbors
[2024-04-12 13:36:13,711: INFO/MainProcess] mingle: all alone
[2024-04-12 13:36:13,732: INFO/MainProcess] celery@ab4b544b2272 ready.
[2024-04-12 13:36:42,758: INFO/MainProcess] Task modules.services.tasks.send_contact_email_message_task[230f9940-cdde-4baa-9f78-3785fc6b4eca] received
[2024-04-12 13:38:53,198: ERROR/ForkPoolWorker-1] Task modules.services.tasks.send_contact_email_message_task[230f9940-cdde-4baa-9f78-3785fc6b4eca] raised unexpected: OSError(101, 'Network unreachable')
Traceback (most recent call last):
  File "/usr/local/lib/python3.12/site-packages/celery/app/trace.py", line 477, in trace_task
    R = retval = fun(*args, **kwargs)
                 ^^^^^^^^^^^^^^^^^^^^
  File "/usr/local/lib/python3.12/site-packages/celery/app/trace.py", line 760, in __protected_call__
    return self.run(*args, **kwargs)
           ^^^^^^^^^^^^^^^^^^^^^^^^^
  File "/app/modules/services/tasks.py", line 22, in send_contact_email_message_task
    return send_contact_email_message(subject, email, content, ip, user_id)
           ^^^^^^^^^^^^^^^^^^^^^^^^^^^^^^^^^^^^^^^^^^^^^^^^^^^^^^^^^^^^^^^^
  File "/app/modules/services/email.py", line 27, in send_contact_email_message
    email.send(fail_silently=False)
  File "/usr/local/lib/python3.12/site-packages/django/core/mail/message.py", line 298, in send
    return self.get_connection(fail_silently).send_messages([self])
           ^^^^^^^^^^^^^^^^^^^^^^^^^^^^^^^^^^^^^^^^^^^^^^^^^^^^^^^^
  File "/usr/local/lib/python3.12/site-packages/django/core/mail/backends/smtp.py", line 127, in send_messages
    new_conn_created = self.open()
                       ^^^^^^^^^^^
  File "/usr/local/lib/python3.12/site-packages/django/core/mail/backends/smtp.py", line 85, in open
    self.connection = self.connection_class(
                      ^^^^^^^^^^^^^^^^^^^^^^
  File "/usr/local/lib/python3.12/smtplib.py", line 255, in __init__
    (code, msg) = self.connect(host, port)
                  ^^^^^^^^^^^^^^^^^^^^^^^^
  File "/usr/local/lib/python3.12/smtplib.py", line 341, in connect
    self.sock = self._get_socket(host, port, self.timeout)
                ^^^^^^^^^^^^^^^^^^^^^^^^^^^^^^^^^^^^^^^^^^
  File "/usr/local/lib/python3.12/smtplib.py", line 312, in _get_socket
    return socket.create_connection((host, port), timeout,
           ^^^^^^^^^^^^^^^^^^^^^^^^^^^^^^^^^^^^^^^^^^^^^^^
  File "/usr/local/lib/python3.12/socket.py", line 852, in create_connection
    raise exceptions[0]
  File "/usr/local/lib/python3.12/socket.py", line 837, in create_connection
    sock.connect(sa)
OSError: [Errno 101] Network unreachable
[2024-04-12 13:44:07,525: WARNING/MainProcess] /usr/local/lib/python3.12/site-packages/celery/worker/consumer/consumer.py:507: CPendingDeprecationWarning: The broker_connection_retry configuration setting will no longer determine
whether broker connection retries are made during startup in Celery 6.0 and above.
If you wish to retain the existing behavior for retrying connections on startup,
you should set broker_connection_retry_on_startup to True.
  warnings.warn(

[2024-04-12 13:44:07,609: INFO/MainProcess] Connected to redis://redis:6379/0
[2024-04-12 13:44:07,617: WARNING/MainProcess] /usr/local/lib/python3.12/site-packages/celery/worker/consumer/consumer.py:507: CPendingDeprecationWarning: The broker_connection_retry configuration setting will no longer determine
whether broker connection retries are made during startup in Celery 6.0 and above.
If you wish to retain the existing behavior for retrying connections on startup,
you should set broker_connection_retry_on_startup to True.
  warnings.warn(

[2024-04-12 13:44:07,625: INFO/MainProcess] mingle: searching for neighbors
[2024-04-12 13:44:08,659: INFO/MainProcess] mingle: all alone
[2024-04-12 13:44:08,706: INFO/MainProcess] celery@ab4b544b2272 ready.
[2024-04-12 13:46:01,647: INFO/MainProcess] Task modules.services.tasks.send_contact_email_message_task[1417667f-01bb-4bdc-bd0c-88729d2609e3] received
[2024-04-12 13:47:42,633: INFO/MainProcess] Task modules.services.tasks.send_activate_email_message_task[6c22b560-f985-4e17-9e12-1f35b4499489] received
[2024-04-12 13:48:12,302: ERROR/ForkPoolWorker-1] Task modules.services.tasks.send_contact_email_message_task[1417667f-01bb-4bdc-bd0c-88729d2609e3] raised unexpected: OSError(101, 'Network unreachable')
Traceback (most recent call last):
  File "/usr/local/lib/python3.12/site-packages/celery/app/trace.py", line 477, in trace_task
    R = retval = fun(*args, **kwargs)
                 ^^^^^^^^^^^^^^^^^^^^
  File "/usr/local/lib/python3.12/site-packages/celery/app/trace.py", line 760, in __protected_call__
    return self.run(*args, **kwargs)
           ^^^^^^^^^^^^^^^^^^^^^^^^^
  File "/app/modules/services/tasks.py", line 22, in send_contact_email_message_task
    return send_contact_email_message(subject, email, content, ip, user_id)
           ^^^^^^^^^^^^^^^^^^^^^^^^^^^^^^^^^^^^^^^^^^^^^^^^^^^^^^^^^^^^^^^^
  File "/app/modules/services/email.py", line 27, in send_contact_email_message
    email.send(fail_silently=False)
  File "/usr/local/lib/python3.12/site-packages/django/core/mail/message.py", line 298, in send
    return self.get_connection(fail_silently).send_messages([self])
           ^^^^^^^^^^^^^^^^^^^^^^^^^^^^^^^^^^^^^^^^^^^^^^^^^^^^^^^^
  File "/usr/local/lib/python3.12/site-packages/django/core/mail/backends/smtp.py", line 127, in send_messages
    new_conn_created = self.open()
                       ^^^^^^^^^^^
  File "/usr/local/lib/python3.12/site-packages/django/core/mail/backends/smtp.py", line 85, in open
    self.connection = self.connection_class(
                      ^^^^^^^^^^^^^^^^^^^^^^
  File "/usr/local/lib/python3.12/smtplib.py", line 255, in __init__
    (code, msg) = self.connect(host, port)
                  ^^^^^^^^^^^^^^^^^^^^^^^^
  File "/usr/local/lib/python3.12/smtplib.py", line 341, in connect
    self.sock = self._get_socket(host, port, self.timeout)
                ^^^^^^^^^^^^^^^^^^^^^^^^^^^^^^^^^^^^^^^^^^
  File "/usr/local/lib/python3.12/smtplib.py", line 312, in _get_socket
    return socket.create_connection((host, port), timeout,
           ^^^^^^^^^^^^^^^^^^^^^^^^^^^^^^^^^^^^^^^^^^^^^^^
  File "/usr/local/lib/python3.12/socket.py", line 852, in create_connection
    raise exceptions[0]
  File "/usr/local/lib/python3.12/socket.py", line 837, in create_connection
    sock.connect(sa)
OSError: [Errno 101] Network unreachable
[2024-04-12 13:50:23,373: ERROR/ForkPoolWorker-1] Task modules.services.tasks.send_activate_email_message_task[6c22b560-f985-4e17-9e12-1f35b4499489] raised unexpected: OSError(101, 'Network unreachable')
Traceback (most recent call last):
  File "/usr/local/lib/python3.12/site-packages/celery/app/trace.py", line 477, in trace_task
    R = retval = fun(*args, **kwargs)
                 ^^^^^^^^^^^^^^^^^^^^
  File "/usr/local/lib/python3.12/site-packages/celery/app/trace.py", line 760, in __protected_call__
    return self.run(*args, **kwargs)
           ^^^^^^^^^^^^^^^^^^^^^^^^^
  File "/app/modules/services/tasks.py", line 13, in send_activate_email_message_task
    return send_activate_email_message(user_id)
           ^^^^^^^^^^^^^^^^^^^^^^^^^^^^^^^^^^^^
  File "/app/modules/services/email.py", line 43, in send_activate_email_message
    return user.email_user(subject, message)
           ^^^^^^^^^^^^^^^^^^^^^^^^^^^^^^^^^
  File "/usr/local/lib/python3.12/site-packages/django/contrib/auth/models.py", line 402, in email_user
    send_mail(subject, message, from_email, [self.email], **kwargs)
  File "/usr/local/lib/python3.12/site-packages/django/core/mail/__init__.py", line 87, in send_mail
    return mail.send()
           ^^^^^^^^^^^
  File "/usr/local/lib/python3.12/site-packages/django/core/mail/message.py", line 298, in send
    return self.get_connection(fail_silently).send_messages([self])
           ^^^^^^^^^^^^^^^^^^^^^^^^^^^^^^^^^^^^^^^^^^^^^^^^^^^^^^^^
  File "/usr/local/lib/python3.12/site-packages/django/core/mail/backends/smtp.py", line 127, in send_messages
    new_conn_created = self.open()
                       ^^^^^^^^^^^
  File "/usr/local/lib/python3.12/site-packages/django/core/mail/backends/smtp.py", line 85, in open
    self.connection = self.connection_class(
                      ^^^^^^^^^^^^^^^^^^^^^^
  File "/usr/local/lib/python3.12/smtplib.py", line 255, in __init__
    (code, msg) = self.connect(host, port)
                  ^^^^^^^^^^^^^^^^^^^^^^^^
  File "/usr/local/lib/python3.12/smtplib.py", line 341, in connect
    self.sock = self._get_socket(host, port, self.timeout)
                ^^^^^^^^^^^^^^^^^^^^^^^^^^^^^^^^^^^^^^^^^^
  File "/usr/local/lib/python3.12/smtplib.py", line 312, in _get_socket
    return socket.create_connection((host, port), timeout,
           ^^^^^^^^^^^^^^^^^^^^^^^^^^^^^^^^^^^^^^^^^^^^^^^
  File "/usr/local/lib/python3.12/socket.py", line 852, in create_connection
    raise exceptions[0]
  File "/usr/local/lib/python3.12/socket.py", line 837, in create_connection
    sock.connect(sa)
OSError: [Errno 101] Network unreachable
[2024-04-12 13:52:34,354: WARNING/MainProcess] /usr/local/lib/python3.12/site-packages/celery/worker/consumer/consumer.py:507: CPendingDeprecationWarning: The broker_connection_retry configuration setting will no longer determine
whether broker connection retries are made during startup in Celery 6.0 and above.
If you wish to retain the existing behavior for retrying connections on startup,
you should set broker_connection_retry_on_startup to True.
  warnings.warn(

[2024-04-12 13:52:34,414: INFO/MainProcess] Connected to redis://redis:6379/0
[2024-04-12 13:52:34,417: WARNING/MainProcess] /usr/local/lib/python3.12/site-packages/celery/worker/consumer/consumer.py:507: CPendingDeprecationWarning: The broker_connection_retry configuration setting will no longer determine
whether broker connection retries are made during startup in Celery 6.0 and above.
If you wish to retain the existing behavior for retrying connections on startup,
you should set broker_connection_retry_on_startup to True.
  warnings.warn(

[2024-04-12 13:52:34,424: INFO/MainProcess] mingle: searching for neighbors
[2024-04-12 13:52:35,445: INFO/MainProcess] mingle: all alone
[2024-04-12 13:52:35,463: INFO/MainProcess] celery@ab4b544b2272 ready.
[2024-04-12 13:52:55,714: WARNING/MainProcess] /usr/local/lib/python3.12/site-packages/celery/worker/consumer/consumer.py:507: CPendingDeprecationWarning: The broker_connection_retry configuration setting will no longer determine
whether broker connection retries are made during startup in Celery 6.0 and above.
If you wish to retain the existing behavior for retrying connections on startup,
you should set broker_connection_retry_on_startup to True.
  warnings.warn(

[2024-04-12 13:52:55,771: INFO/MainProcess] Connected to redis://redis:6379/0
[2024-04-12 13:52:55,773: WARNING/MainProcess] /usr/local/lib/python3.12/site-packages/celery/worker/consumer/consumer.py:507: CPendingDeprecationWarning: The broker_connection_retry configuration setting will no longer determine
whether broker connection retries are made during startup in Celery 6.0 and above.
If you wish to retain the existing behavior for retrying connections on startup,
you should set broker_connection_retry_on_startup to True.
  warnings.warn(

[2024-04-12 13:52:55,781: INFO/MainProcess] mingle: searching for neighbors
[2024-04-12 13:52:56,801: INFO/MainProcess] mingle: all alone
[2024-04-12 13:52:56,835: INFO/MainProcess] celery@ab4b544b2272 ready.
[2024-04-12 13:57:35,057: WARNING/MainProcess] /usr/local/lib/python3.12/site-packages/celery/worker/consumer/consumer.py:507: CPendingDeprecationWarning: The broker_connection_retry configuration setting will no longer determine
whether broker connection retries are made during startup in Celery 6.0 and above.
If you wish to retain the existing behavior for retrying connections on startup,
you should set broker_connection_retry_on_startup to True.
  warnings.warn(

[2024-04-12 13:57:40,082: ERROR/MainProcess] consumer: Cannot connect to redis://redis:6379/0: Error -3 connecting to redis:6379. Try again..
Trying again in 2.00 seconds... (1/100)

[2024-04-12 13:57:47,090: ERROR/MainProcess] consumer: Cannot connect to redis://redis:6379/0: Error -3 connecting to redis:6379. Try again..
Trying again in 4.00 seconds... (2/100)

[2024-04-12 13:57:56,097: ERROR/MainProcess] consumer: Cannot connect to redis://redis:6379/0: Error -3 connecting to redis:6379. Try again..
Trying again in 6.00 seconds... (3/100)

[2024-04-12 13:58:07,103: ERROR/MainProcess] consumer: Cannot connect to redis://redis:6379/0: Error -3 connecting to redis:6379. Try again..
Trying again in 8.00 seconds... (4/100)

[2024-04-12 13:58:20,110: ERROR/MainProcess] consumer: Cannot connect to redis://redis:6379/0: Error -3 connecting to redis:6379. Try again..
Trying again in 10.00 seconds... (5/100)

[2024-04-12 13:58:35,118: ERROR/MainProcess] consumer: Cannot connect to redis://redis:6379/0: Error -3 connecting to redis:6379. Try again..
Trying again in 12.00 seconds... (6/100)

[2024-04-12 13:58:52,128: ERROR/MainProcess] consumer: Cannot connect to redis://redis:6379/0: Error -3 connecting to redis:6379. Try again..
Trying again in 14.00 seconds... (7/100)

[2024-04-12 13:59:11,138: ERROR/MainProcess] consumer: Cannot connect to redis://redis:6379/0: Error -3 connecting to redis:6379. Try again..
Trying again in 16.00 seconds... (8/100)

[2024-04-12 13:59:28,194: INFO/MainProcess] Connected to redis://redis:6379/0
[2024-04-12 13:59:28,244: WARNING/MainProcess] /usr/local/lib/python3.12/site-packages/celery/worker/consumer/consumer.py:507: CPendingDeprecationWarning: The broker_connection_retry configuration setting will no longer determine
whether broker connection retries are made during startup in Celery 6.0 and above.
If you wish to retain the existing behavior for retrying connections on startup,
you should set broker_connection_retry_on_startup to True.
  warnings.warn(

[2024-04-12 13:59:28,307: INFO/MainProcess] mingle: searching for neighbors
[2024-04-12 13:59:29,370: INFO/MainProcess] mingle: all alone
[2024-04-12 13:59:29,421: INFO/MainProcess] celery@ab4b544b2272 ready.
[2024-04-12 14:06:37,871: WARNING/MainProcess] /usr/local/lib/python3.12/site-packages/celery/worker/consumer/consumer.py:507: CPendingDeprecationWarning: The broker_connection_retry configuration setting will no longer determine
whether broker connection retries are made during startup in Celery 6.0 and above.
If you wish to retain the existing behavior for retrying connections on startup,
you should set broker_connection_retry_on_startup to True.
  warnings.warn(

[2024-04-12 14:06:37,921: INFO/MainProcess] Connected to redis://redis:6379/0
[2024-04-12 14:06:37,923: WARNING/MainProcess] /usr/local/lib/python3.12/site-packages/celery/worker/consumer/consumer.py:507: CPendingDeprecationWarning: The broker_connection_retry configuration setting will no longer determine
whether broker connection retries are made during startup in Celery 6.0 and above.
If you wish to retain the existing behavior for retrying connections on startup,
you should set broker_connection_retry_on_startup to True.
  warnings.warn(

[2024-04-12 14:06:37,929: INFO/MainProcess] mingle: searching for neighbors
[2024-04-12 14:06:38,948: INFO/MainProcess] mingle: all alone
[2024-04-12 14:06:38,981: INFO/MainProcess] celery@ab4b544b2272 ready.
[2024-04-12 14:06:38,990: INFO/MainProcess] Task modules.services.tasks.send_activate_email_message_task[692de6d5-fadb-4e31-bc74-d6a1046ca0b2] received
[2024-04-12 14:08:50,096: ERROR/ForkPoolWorker-1] Task modules.services.tasks.send_activate_email_message_task[692de6d5-fadb-4e31-bc74-d6a1046ca0b2] raised unexpected: OSError(101, 'Network unreachable')
Traceback (most recent call last):
  File "/usr/local/lib/python3.12/site-packages/celery/app/trace.py", line 477, in trace_task
    R = retval = fun(*args, **kwargs)
                 ^^^^^^^^^^^^^^^^^^^^
  File "/usr/local/lib/python3.12/site-packages/celery/app/trace.py", line 760, in __protected_call__
    return self.run(*args, **kwargs)
           ^^^^^^^^^^^^^^^^^^^^^^^^^
  File "/app/modules/services/tasks.py", line 13, in send_activate_email_message_task
    return send_activate_email_message(user_id)
           ^^^^^^^^^^^^^^^^^^^^^^^^^^^^^^^^^^^^
  File "/app/modules/services/email.py", line 43, in send_activate_email_message
    return user.email_user(subject, message)
           ^^^^^^^^^^^^^^^^^^^^^^^^^^^^^^^^^
  File "/usr/local/lib/python3.12/site-packages/django/contrib/auth/models.py", line 402, in email_user
    send_mail(subject, message, from_email, [self.email], **kwargs)
  File "/usr/local/lib/python3.12/site-packages/django/core/mail/__init__.py", line 87, in send_mail
    return mail.send()
           ^^^^^^^^^^^
  File "/usr/local/lib/python3.12/site-packages/django/core/mail/message.py", line 298, in send
    return self.get_connection(fail_silently).send_messages([self])
           ^^^^^^^^^^^^^^^^^^^^^^^^^^^^^^^^^^^^^^^^^^^^^^^^^^^^^^^^
  File "/usr/local/lib/python3.12/site-packages/django/core/mail/backends/smtp.py", line 127, in send_messages
    new_conn_created = self.open()
                       ^^^^^^^^^^^
  File "/usr/local/lib/python3.12/site-packages/django/core/mail/backends/smtp.py", line 85, in open
    self.connection = self.connection_class(
                      ^^^^^^^^^^^^^^^^^^^^^^
  File "/usr/local/lib/python3.12/smtplib.py", line 255, in __init__
    (code, msg) = self.connect(host, port)
                  ^^^^^^^^^^^^^^^^^^^^^^^^
  File "/usr/local/lib/python3.12/smtplib.py", line 341, in connect
    self.sock = self._get_socket(host, port, self.timeout)
                ^^^^^^^^^^^^^^^^^^^^^^^^^^^^^^^^^^^^^^^^^^
  File "/usr/local/lib/python3.12/smtplib.py", line 312, in _get_socket
    return socket.create_connection((host, port), timeout,
           ^^^^^^^^^^^^^^^^^^^^^^^^^^^^^^^^^^^^^^^^^^^^^^^
  File "/usr/local/lib/python3.12/socket.py", line 852, in create_connection
    raise exceptions[0]
  File "/usr/local/lib/python3.12/socket.py", line 837, in create_connection
    sock.connect(sa)
OSError: [Errno 101] Network unreachable
[2024-04-12 14:09:52,263: INFO/MainProcess] Task modules.services.tasks.send_activate_email_message_task[f5922d47-735e-473b-a7cb-9cb4451db898] received
[2024-04-12 14:12:02,605: ERROR/ForkPoolWorker-1] Task modules.services.tasks.send_activate_email_message_task[f5922d47-735e-473b-a7cb-9cb4451db898] raised unexpected: OSError(101, 'Network unreachable')
Traceback (most recent call last):
  File "/usr/local/lib/python3.12/site-packages/celery/app/trace.py", line 477, in trace_task
    R = retval = fun(*args, **kwargs)
                 ^^^^^^^^^^^^^^^^^^^^
  File "/usr/local/lib/python3.12/site-packages/celery/app/trace.py", line 760, in __protected_call__
    return self.run(*args, **kwargs)
           ^^^^^^^^^^^^^^^^^^^^^^^^^
  File "/app/modules/services/tasks.py", line 13, in send_activate_email_message_task
    return send_activate_email_message(user_id)
           ^^^^^^^^^^^^^^^^^^^^^^^^^^^^^^^^^^^^
  File "/app/modules/services/email.py", line 43, in send_activate_email_message
    return user.email_user(subject, message)
           ^^^^^^^^^^^^^^^^^^^^^^^^^^^^^^^^^
  File "/usr/local/lib/python3.12/site-packages/django/contrib/auth/models.py", line 402, in email_user
    send_mail(subject, message, from_email, [self.email], **kwargs)
  File "/usr/local/lib/python3.12/site-packages/django/core/mail/__init__.py", line 87, in send_mail
    return mail.send()
           ^^^^^^^^^^^
  File "/usr/local/lib/python3.12/site-packages/django/core/mail/message.py", line 298, in send
    return self.get_connection(fail_silently).send_messages([self])
           ^^^^^^^^^^^^^^^^^^^^^^^^^^^^^^^^^^^^^^^^^^^^^^^^^^^^^^^^
  File "/usr/local/lib/python3.12/site-packages/django/core/mail/backends/smtp.py", line 127, in send_messages
    new_conn_created = self.open()
                       ^^^^^^^^^^^
  File "/usr/local/lib/python3.12/site-packages/django/core/mail/backends/smtp.py", line 85, in open
    self.connection = self.connection_class(
                      ^^^^^^^^^^^^^^^^^^^^^^
  File "/usr/local/lib/python3.12/smtplib.py", line 255, in __init__
    (code, msg) = self.connect(host, port)
                  ^^^^^^^^^^^^^^^^^^^^^^^^
  File "/usr/local/lib/python3.12/smtplib.py", line 341, in connect
    self.sock = self._get_socket(host, port, self.timeout)
                ^^^^^^^^^^^^^^^^^^^^^^^^^^^^^^^^^^^^^^^^^^
  File "/usr/local/lib/python3.12/smtplib.py", line 312, in _get_socket
    return socket.create_connection((host, port), timeout,
           ^^^^^^^^^^^^^^^^^^^^^^^^^^^^^^^^^^^^^^^^^^^^^^^
  File "/usr/local/lib/python3.12/socket.py", line 852, in create_connection
    raise exceptions[0]
  File "/usr/local/lib/python3.12/socket.py", line 837, in create_connection
    sock.connect(sa)
OSError: [Errno 101] Network unreachable
[2024-04-12 14:12:46,821: INFO/MainProcess] Task modules.services.tasks.send_activate_email_message_task[0db853e0-943d-4f4c-9f66-577db8b089f8] received
[2024-04-12 14:14:56,687: ERROR/ForkPoolWorker-1] Task modules.services.tasks.send_activate_email_message_task[0db853e0-943d-4f4c-9f66-577db8b089f8] raised unexpected: OSError(101, 'Network unreachable')
Traceback (most recent call last):
  File "/usr/local/lib/python3.12/site-packages/celery/app/trace.py", line 477, in trace_task
    R = retval = fun(*args, **kwargs)
                 ^^^^^^^^^^^^^^^^^^^^
  File "/usr/local/lib/python3.12/site-packages/celery/app/trace.py", line 760, in __protected_call__
    return self.run(*args, **kwargs)
           ^^^^^^^^^^^^^^^^^^^^^^^^^
  File "/app/modules/services/tasks.py", line 13, in send_activate_email_message_task
    return send_activate_email_message(user_id)
           ^^^^^^^^^^^^^^^^^^^^^^^^^^^^^^^^^^^^
  File "/app/modules/services/email.py", line 43, in send_activate_email_message
    return user.email_user(subject, message)
           ^^^^^^^^^^^^^^^^^^^^^^^^^^^^^^^^^
  File "/usr/local/lib/python3.12/site-packages/django/contrib/auth/models.py", line 402, in email_user
    send_mail(subject, message, from_email, [self.email], **kwargs)
  File "/usr/local/lib/python3.12/site-packages/django/core/mail/__init__.py", line 87, in send_mail
    return mail.send()
           ^^^^^^^^^^^
  File "/usr/local/lib/python3.12/site-packages/django/core/mail/message.py", line 298, in send
    return self.get_connection(fail_silently).send_messages([self])
           ^^^^^^^^^^^^^^^^^^^^^^^^^^^^^^^^^^^^^^^^^^^^^^^^^^^^^^^^
  File "/usr/local/lib/python3.12/site-packages/django/core/mail/backends/smtp.py", line 127, in send_messages
    new_conn_created = self.open()
                       ^^^^^^^^^^^
  File "/usr/local/lib/python3.12/site-packages/django/core/mail/backends/smtp.py", line 85, in open
    self.connection = self.connection_class(
                      ^^^^^^^^^^^^^^^^^^^^^^
  File "/usr/local/lib/python3.12/smtplib.py", line 255, in __init__
    (code, msg) = self.connect(host, port)
                  ^^^^^^^^^^^^^^^^^^^^^^^^
  File "/usr/local/lib/python3.12/smtplib.py", line 341, in connect
    self.sock = self._get_socket(host, port, self.timeout)
                ^^^^^^^^^^^^^^^^^^^^^^^^^^^^^^^^^^^^^^^^^^
  File "/usr/local/lib/python3.12/smtplib.py", line 312, in _get_socket
    return socket.create_connection((host, port), timeout,
           ^^^^^^^^^^^^^^^^^^^^^^^^^^^^^^^^^^^^^^^^^^^^^^^
  File "/usr/local/lib/python3.12/socket.py", line 852, in create_connection
    raise exceptions[0]
  File "/usr/local/lib/python3.12/socket.py", line 837, in create_connection
    sock.connect(sa)
OSError: [Errno 101] Network unreachable
[2024-04-12 14:21:18,348: INFO/MainProcess] Task modules.services.tasks.send_activate_email_message_task[e5156833-11dd-4034-9724-bf04d79f589d] received
[2024-04-12 14:22:33,467: INFO/MainProcess] Task modules.services.tasks.send_activate_email_message_task[d1ee4b06-104d-43f9-9ea1-8b2bc873b3f1] received
[2024-04-12 14:23:28,683: ERROR/ForkPoolWorker-1] Task modules.services.tasks.send_activate_email_message_task[e5156833-11dd-4034-9724-bf04d79f589d] raised unexpected: OSError(101, 'Network unreachable')
Traceback (most recent call last):
  File "/usr/local/lib/python3.12/site-packages/celery/app/trace.py", line 477, in trace_task
    R = retval = fun(*args, **kwargs)
                 ^^^^^^^^^^^^^^^^^^^^
  File "/usr/local/lib/python3.12/site-packages/celery/app/trace.py", line 760, in __protected_call__
    return self.run(*args, **kwargs)
           ^^^^^^^^^^^^^^^^^^^^^^^^^
  File "/app/modules/services/tasks.py", line 13, in send_activate_email_message_task
    return send_activate_email_message(user_id)
           ^^^^^^^^^^^^^^^^^^^^^^^^^^^^^^^^^^^^
  File "/app/modules/services/email.py", line 43, in send_activate_email_message
    return user.email_user(subject, message)
           ^^^^^^^^^^^^^^^^^^^^^^^^^^^^^^^^^
  File "/usr/local/lib/python3.12/site-packages/django/contrib/auth/models.py", line 402, in email_user
    send_mail(subject, message, from_email, [self.email], **kwargs)
  File "/usr/local/lib/python3.12/site-packages/django/core/mail/__init__.py", line 87, in send_mail
    return mail.send()
           ^^^^^^^^^^^
  File "/usr/local/lib/python3.12/site-packages/django/core/mail/message.py", line 298, in send
    return self.get_connection(fail_silently).send_messages([self])
           ^^^^^^^^^^^^^^^^^^^^^^^^^^^^^^^^^^^^^^^^^^^^^^^^^^^^^^^^
  File "/usr/local/lib/python3.12/site-packages/django/core/mail/backends/smtp.py", line 127, in send_messages
    new_conn_created = self.open()
                       ^^^^^^^^^^^
  File "/usr/local/lib/python3.12/site-packages/django/core/mail/backends/smtp.py", line 85, in open
    self.connection = self.connection_class(
                      ^^^^^^^^^^^^^^^^^^^^^^
  File "/usr/local/lib/python3.12/smtplib.py", line 255, in __init__
    (code, msg) = self.connect(host, port)
                  ^^^^^^^^^^^^^^^^^^^^^^^^
  File "/usr/local/lib/python3.12/smtplib.py", line 341, in connect
    self.sock = self._get_socket(host, port, self.timeout)
                ^^^^^^^^^^^^^^^^^^^^^^^^^^^^^^^^^^^^^^^^^^
  File "/usr/local/lib/python3.12/smtplib.py", line 312, in _get_socket
    return socket.create_connection((host, port), timeout,
           ^^^^^^^^^^^^^^^^^^^^^^^^^^^^^^^^^^^^^^^^^^^^^^^
  File "/usr/local/lib/python3.12/socket.py", line 852, in create_connection
    raise exceptions[0]
  File "/usr/local/lib/python3.12/socket.py", line 837, in create_connection
    sock.connect(sa)
OSError: [Errno 101] Network unreachable
[2024-04-12 14:25:39,756: ERROR/ForkPoolWorker-1] Task modules.services.tasks.send_activate_email_message_task[d1ee4b06-104d-43f9-9ea1-8b2bc873b3f1] raised unexpected: OSError(101, 'Network unreachable')
Traceback (most recent call last):
  File "/usr/local/lib/python3.12/site-packages/celery/app/trace.py", line 477, in trace_task
    R = retval = fun(*args, **kwargs)
                 ^^^^^^^^^^^^^^^^^^^^
  File "/usr/local/lib/python3.12/site-packages/celery/app/trace.py", line 760, in __protected_call__
    return self.run(*args, **kwargs)
           ^^^^^^^^^^^^^^^^^^^^^^^^^
  File "/app/modules/services/tasks.py", line 13, in send_activate_email_message_task
    return send_activate_email_message(user_id)
           ^^^^^^^^^^^^^^^^^^^^^^^^^^^^^^^^^^^^
  File "/app/modules/services/email.py", line 43, in send_activate_email_message
    return user.email_user(subject, message)
           ^^^^^^^^^^^^^^^^^^^^^^^^^^^^^^^^^
  File "/usr/local/lib/python3.12/site-packages/django/contrib/auth/models.py", line 402, in email_user
    send_mail(subject, message, from_email, [self.email], **kwargs)
  File "/usr/local/lib/python3.12/site-packages/django/core/mail/__init__.py", line 87, in send_mail
    return mail.send()
           ^^^^^^^^^^^
  File "/usr/local/lib/python3.12/site-packages/django/core/mail/message.py", line 298, in send
    return self.get_connection(fail_silently).send_messages([self])
           ^^^^^^^^^^^^^^^^^^^^^^^^^^^^^^^^^^^^^^^^^^^^^^^^^^^^^^^^
  File "/usr/local/lib/python3.12/site-packages/django/core/mail/backends/smtp.py", line 127, in send_messages
    new_conn_created = self.open()
                       ^^^^^^^^^^^
  File "/usr/local/lib/python3.12/site-packages/django/core/mail/backends/smtp.py", line 85, in open
    self.connection = self.connection_class(
                      ^^^^^^^^^^^^^^^^^^^^^^
  File "/usr/local/lib/python3.12/smtplib.py", line 255, in __init__
    (code, msg) = self.connect(host, port)
                  ^^^^^^^^^^^^^^^^^^^^^^^^
  File "/usr/local/lib/python3.12/smtplib.py", line 341, in connect
    self.sock = self._get_socket(host, port, self.timeout)
                ^^^^^^^^^^^^^^^^^^^^^^^^^^^^^^^^^^^^^^^^^^
  File "/usr/local/lib/python3.12/smtplib.py", line 312, in _get_socket
    return socket.create_connection((host, port), timeout,
           ^^^^^^^^^^^^^^^^^^^^^^^^^^^^^^^^^^^^^^^^^^^^^^^
  File "/usr/local/lib/python3.12/socket.py", line 852, in create_connection
    raise exceptions[0]
  File "/usr/local/lib/python3.12/socket.py", line 837, in create_connection
    sock.connect(sa)
OSError: [Errno 101] Network unreachable
[2024-04-12 15:01:37,410: WARNING/MainProcess] /usr/local/lib/python3.12/site-packages/celery/worker/consumer/consumer.py:507: CPendingDeprecationWarning: The broker_connection_retry configuration setting will no longer determine
whether broker connection retries are made during startup in Celery 6.0 and above.
If you wish to retain the existing behavior for retrying connections on startup,
you should set broker_connection_retry_on_startup to True.
  warnings.warn(

[2024-04-12 15:01:37,500: INFO/MainProcess] Connected to redis://redis:6379/0
[2024-04-12 15:01:37,515: WARNING/MainProcess] /usr/local/lib/python3.12/site-packages/celery/worker/consumer/consumer.py:507: CPendingDeprecationWarning: The broker_connection_retry configuration setting will no longer determine
whether broker connection retries are made during startup in Celery 6.0 and above.
If you wish to retain the existing behavior for retrying connections on startup,
you should set broker_connection_retry_on_startup to True.
  warnings.warn(

[2024-04-12 15:01:37,533: INFO/MainProcess] mingle: searching for neighbors
[2024-04-12 15:01:38,571: INFO/MainProcess] mingle: all alone
[2024-04-12 15:01:38,628: INFO/MainProcess] celery@0f4aa57f8c46 ready.
[2024-04-12 15:01:38,648: INFO/MainProcess] Task modules.services.tasks.dbackup_task[b9826527-c257-42b8-ac45-82fd04f84dab] received
[2024-04-12 15:01:38,746: WARNING/ForkPoolWorker-1] Waiting for database dump...
[2024-04-12 15:01:39,628: WARNING/ForkPoolWorker-1] Database successfully backed up
[2024-04-12 15:01:39,639: INFO/ForkPoolWorker-1] Task modules.services.tasks.dbackup_task[b9826527-c257-42b8-ac45-82fd04f84dab] succeeded in 0.9889261829998759s: None
[2024-04-12 15:02:54,645: INFO/MainProcess] Task modules.services.tasks.send_activate_email_message_task[bff7fe18-ce61-4222-b40f-375de42b2ca7] received
[2024-04-12 15:05:05,205: ERROR/ForkPoolWorker-1] Task modules.services.tasks.send_activate_email_message_task[bff7fe18-ce61-4222-b40f-375de42b2ca7] raised unexpected: OSError(101, 'Network unreachable')
Traceback (most recent call last):
  File "/usr/local/lib/python3.12/site-packages/celery/app/trace.py", line 477, in trace_task
    R = retval = fun(*args, **kwargs)
                 ^^^^^^^^^^^^^^^^^^^^
  File "/usr/local/lib/python3.12/site-packages/celery/app/trace.py", line 760, in __protected_call__
    return self.run(*args, **kwargs)
           ^^^^^^^^^^^^^^^^^^^^^^^^^
  File "/app/modules/services/tasks.py", line 13, in send_activate_email_message_task
    return send_activate_email_message(user_id)
           ^^^^^^^^^^^^^^^^^^^^^^^^^^^^^^^^^^^^
  File "/app/modules/services/email.py", line 43, in send_activate_email_message
    return user.email_user(subject, message)
           ^^^^^^^^^^^^^^^^^^^^^^^^^^^^^^^^^
  File "/usr/local/lib/python3.12/site-packages/django/contrib/auth/models.py", line 402, in email_user
    send_mail(subject, message, from_email, [self.email], **kwargs)
  File "/usr/local/lib/python3.12/site-packages/django/core/mail/__init__.py", line 87, in send_mail
    return mail.send()
           ^^^^^^^^^^^
  File "/usr/local/lib/python3.12/site-packages/django/core/mail/message.py", line 298, in send
    return self.get_connection(fail_silently).send_messages([self])
           ^^^^^^^^^^^^^^^^^^^^^^^^^^^^^^^^^^^^^^^^^^^^^^^^^^^^^^^^
  File "/usr/local/lib/python3.12/site-packages/django/core/mail/backends/smtp.py", line 127, in send_messages
    new_conn_created = self.open()
                       ^^^^^^^^^^^
  File "/usr/local/lib/python3.12/site-packages/django/core/mail/backends/smtp.py", line 85, in open
    self.connection = self.connection_class(
                      ^^^^^^^^^^^^^^^^^^^^^^
  File "/usr/local/lib/python3.12/smtplib.py", line 255, in __init__
    (code, msg) = self.connect(host, port)
                  ^^^^^^^^^^^^^^^^^^^^^^^^
  File "/usr/local/lib/python3.12/smtplib.py", line 341, in connect
    self.sock = self._get_socket(host, port, self.timeout)
                ^^^^^^^^^^^^^^^^^^^^^^^^^^^^^^^^^^^^^^^^^^
  File "/usr/local/lib/python3.12/smtplib.py", line 312, in _get_socket
    return socket.create_connection((host, port), timeout,
           ^^^^^^^^^^^^^^^^^^^^^^^^^^^^^^^^^^^^^^^^^^^^^^^
  File "/usr/local/lib/python3.12/socket.py", line 852, in create_connection
    raise exceptions[0]
  File "/usr/local/lib/python3.12/socket.py", line 837, in create_connection
    sock.connect(sa)
OSError: [Errno 101] Network unreachable
[2024-04-12 15:31:57,840: WARNING/MainProcess] /usr/local/lib/python3.12/site-packages/celery/worker/consumer/consumer.py:507: CPendingDeprecationWarning: The broker_connection_retry configuration setting will no longer determine
whether broker connection retries are made during startup in Celery 6.0 and above.
If you wish to retain the existing behavior for retrying connections on startup,
you should set broker_connection_retry_on_startup to True.
  warnings.warn(

[2024-04-12 15:31:57,905: INFO/MainProcess] Connected to redis://redis:6379/0
[2024-04-12 15:31:57,906: WARNING/MainProcess] /usr/local/lib/python3.12/site-packages/celery/worker/consumer/consumer.py:507: CPendingDeprecationWarning: The broker_connection_retry configuration setting will no longer determine
whether broker connection retries are made during startup in Celery 6.0 and above.
If you wish to retain the existing behavior for retrying connections on startup,
you should set broker_connection_retry_on_startup to True.
  warnings.warn(

[2024-04-12 15:31:57,914: INFO/MainProcess] mingle: searching for neighbors
[2024-04-12 15:31:58,941: INFO/MainProcess] mingle: all alone
[2024-04-12 15:31:58,992: INFO/MainProcess] celery@7d1e18487227 ready.
[2024-04-12 15:33:20,591: INFO/MainProcess] Task modules.services.tasks.send_activate_email_message_task[4c37a7f8-986a-4c1f-906d-e9b9d11373bc] received
[2024-04-12 15:33:21,361: INFO/ForkPoolWorker-1] Task modules.services.tasks.send_activate_email_message_task[4c37a7f8-986a-4c1f-906d-e9b9d11373bc] succeeded in 0.7633599029995821s: None
[2024-04-12 16:37:00,994: INFO/MainProcess] Task modules.services.tasks.send_activate_email_message_task[fe57bfd2-a662-43fc-8dc3-dd295a553000] received
[2024-04-12 16:37:01,708: INFO/ForkPoolWorker-1] Task modules.services.tasks.send_activate_email_message_task[fe57bfd2-a662-43fc-8dc3-dd295a553000] succeeded in 0.7105221320016426s: None
